<sdf version='1.7'>
  <world name='default'>
    <light name='sun' type='directional'>
      <cast_shadows>1</cast_shadows>
      <pose>0 0 10 0 -0 0</pose>
      <diffuse>0.8 0.8 0.8 1</diffuse>
      <specular>0.2 0.2 0.2 1</specular>
      <attenuation>
        <range>1000</range>
        <constant>0.9</constant>
        <linear>0.01</linear>
        <quadratic>0.001</quadratic>
      </attenuation>
      <direction>-0.5 0.1 -0.9</direction>
      <spot>
        <inner_angle>0</inner_angle>
        <outer_angle>0</outer_angle>
        <falloff>0</falloff>
      </spot>
    </light>
    <model name='ground_plane'>
      <static>1</static>
      <link name='link'>
        <collision name='collision'>
          <geometry>
            <plane>
              <normal>0 0 1</normal>
              <size>100 100</size>
            </plane>
          </geometry>
          <surface>
            <friction>
              <ode>
                <mu>100</mu>
                <mu2>50</mu2>
              </ode>
              <torsional>
                <ode/>
              </torsional>
            </friction>
            <contact>
              <ode/>
            </contact>
            <bounce/>
          </surface>
          <max_contacts>10</max_contacts>
        </collision>
        <visual name='visual'>
          <cast_shadows>0</cast_shadows>
          <geometry>
            <plane>
              <normal>0 0 1</normal>
              <size>100 100</size>
            </plane>
          </geometry>
          <material>
            <script>
              <uri>file://media/materials/scripts/gazebo.material</uri>
              <name>Gazebo/Grey</name>
            </script>
          </material>
        </visual>
        <self_collide>0</self_collide>
        <enable_wind>0</enable_wind>
        <kinematic>0</kinematic>
      </link>
    </model>
    <model name='omni_robot'>
      <link name='base_footprint'>
        <self_collide>0</self_collide>
        <inertial>
          <pose>0 0 0 0 -0 0</pose>
          <inertia>
            <ixx>1</ixx>
            <ixy>0</ixy>
            <ixz>0</ixz>
            <iyy>1</iyy>
            <iyz>0</iyz>
            <izz>1</izz>
          </inertia>
          <mass>1</mass>
        </inertial>
        <enable_wind>0</enable_wind>
        <kinematic>0</kinematic>
      </link>
      <link name='base_link'>
        <inertial>
          <pose>0 0 0 0 -0 0</pose>
          <mass>1.167</mass>
          <inertia>
            <ixx>0.0016</ixx>
            <ixy>0</ixy>
            <ixz>0</ixz>
            <iyy>0.0016</iyy>
            <iyz>0</iyz>
            <izz>0.0032</izz>
          </inertia>
        </inertial>
        <collision name='base_footprint_fixed_joint_lump__base_link_collision'>
          <pose>0 0 0 0 -0 0</pose>
          <geometry>
            <mesh>
              <scale>1 1 1</scale>
              <uri>model://rs_robot/meshes/STL/base/base_link.stl</uri>
            </mesh>
          </geometry>
          <surface>
            <contact>
              <ode/>
            </contact>
            <friction>
              <ode>
                <mu>0.05</mu>
                <mu2>0.05</mu2>
              </ode>
              <torsional>
                <ode/>
              </torsional>
            </friction>
            <bounce/>
          </surface>
          <max_contacts>10</max_contacts>
        </collision>
        <visual name='base_footprint_fixed_joint_lump__base_link_visual'>
          <pose>0 0 0 0 -0 0</pose>
          <geometry>
            <mesh>
              <scale>1 1 1</scale>
              <uri>model://rs_robot/meshes/DAE/base/base_link.dae</uri>
            </mesh>
          </geometry>
        </visual>
        <self_collide>0</self_collide>
        <sensor name='front_lrf_sensor' type='ray'>
          <always_on>1</always_on>
          <visualize>0</visualize>
          <update_rate>40</update_rate>
          <pose>0 0 0.1395 0 -0 0</pose>
          <ray>
            <scan>
              <horizontal>
                <samples>720</samples>
                <resolution>1</resolution>
                <min_angle>-3.14158</min_angle>
                <max_angle>3.14158</max_angle>
              </horizontal>
              <vertical>
                <samples>1</samples>
                <min_angle>0</min_angle>
                <max_angle>0</max_angle>
              </vertical>
            </scan>
            <range>
              <min>0.12</min>
              <max>20</max>
              <resolution>0.015</resolution>
            </range>
            <noise>
              <type>gaussian</type>
              <mean>0</mean>
              <stddev>0.01</stddev>
            </noise>
          </ray>
          <plugin name='omni_laserscan' filename='libgazebo_ros_ray_sensor.so'>
            <ros>
              <remapping>~/out:=scan</remapping>
            </ros>
            <output_type>sensor_msgs/LaserScan</output_type>
            <frame_name>front_lrf_link</frame_name>
          </plugin>
        </sensor>
        <enable_wind>0</enable_wind>
        <kinematic>0</kinematic>
      </link>
      <joint name='first_wheel_joint' type='revolute'>
        <pose relative_to='base_link'>0.086338 -0.086338 -0.022 0 0 -2.3562</pose>
        <parent>base_link</parent>
        <child>first_wheel_link</child>
        <axis>
          <xyz>0 1 0</xyz>
          <limit>
            <effort>100</effort>
            <velocity>100</velocity>
            <lower>-1e+16</lower>
            <upper>1e+16</upper>
          </limit>
          <dynamics>
            <spring_reference>0</spring_reference>
            <spring_stiffness>0</spring_stiffness>
          </dynamics>
        </axis>
      </joint>
      <link name='first_wheel_link'>
        <pose relative_to='first_wheel_joint'>0 0 0 0 -0 0</pose>
        <inertial>
          <pose>0 -0.011 0 0 -0 0</pose>
          <mass>0.25</mass>
          <inertia>
            <ixx>0.00031</ixx>
            <ixy>0</ixy>
            <ixz>0</ixz>
            <iyy>0.0005</iyy>
            <iyz>0</iyz>
            <izz>0.00031</izz>
          </inertia>
        </inertial>
        <collision name='first_wheel_link_collision'>
          <pose>0 0 0 0 -0 0</pose>
          <geometry>
            <mesh>
              <scale>1 1 1</scale>
              <uri>model://rs_robot/meshes/STL/omni_wheel/omni_wheel.stl</uri>
            </mesh>
          </geometry>
          <surface>
            <contact>
              <ode>
                <max_vel>0.01</max_vel>
              </ode>
            </contact>
            <friction>
              <ode>
                <mu>1.5</mu>
                <mu2>1.5</mu2>
                <kp>1e15</kp>
                <kd>1e13</kd>
              </ode>
              <torsional>
                <ode/>
              </torsional>
            </friction>
            <bounce>
              <restitution_coefficient>0.01</restitution_coefficient>
              <threshold>0</threshold>
            </bounce>
          </surface>
          <max_contacts>10</max_contacts>
        </collision>
        <visual name='first_wheel_link_visual'>
          <pose>0 0 0 0 -0 0</pose>
          <geometry>
            <mesh>
              <scale>1 1 1</scale>
              <uri>model://rs_robot/meshes/DAE/omni_wheel/omni_wheel.dae</uri>
            </mesh>
          </geometry>
        </visual>
        <self_collide>0</self_collide>
        <enable_wind>0</enable_wind>
        <kinematic>0</kinematic>
      </link>
      <joint name='r10_F_roller_joint' type='revolute'>
        <pose relative_to='first_wheel_link'>-0.022885 0.006 -0.007436 1.25664 -0 1.5708</pose>
        <parent>first_wheel_link</parent>
        <child>r10_F_roller_link</child>
        <axis>
          <xyz>0 1 0</xyz>
          <limit>
            <lower>-1e+16</lower>
            <upper>1e+16</upper>
          </limit>
          <dynamics>
            <spring_reference>0</spring_reference>
            <spring_stiffness>0</spring_stiffness>
          </dynamics>
        </axis>
      </joint>
      <link name='r10_F_roller_link'>
        <pose relative_to='r10_F_roller_joint'>0 0 0 0 -0 0</pose>
        <inertial>
          <pose>0 0 0 0 -0 0</pose>
          <mass>0.009</mass>
          <inertia>
            <ixx>1.257e-06</ixx>
            <ixy>0</ixy>
            <ixz>0</ixz>
            <iyy>3.42e-07</iyy>
            <iyz>0</iyz>
            <izz>1.257e-06</izz>
          </inertia>
        </inertial>
        <collision name='r10_F_roller_link_collision'>
          <pose>0 0 0 0 -0 0</pose>
          <geometry>
            <mesh>
              <scale>1 1 1</scale>
              <uri>model://rs_robot/meshes/STL/roller/roller.stl</uri>
            </mesh>
          </geometry>
          <surface>
            <contact>
              <ode>
                <max_vel>0.01</max_vel>
              </ode>
            </contact>
            <friction>
              <ode>
                <mu>1.5</mu>
                <mu2>1.5</mu2>
                <kp>1e15</kp>
                <kd>1e13</kd>
              </ode>
              <torsional>
                <ode/>
              </torsional>
            </friction>
            <bounce>
              <restitution_coefficient>0.01</restitution_coefficient>
              <threshold>0</threshold>
            </bounce>
          </surface>
          <max_contacts>10</max_contacts>
        </collision>
        <visual name='r10_F_roller_link_visual'>
          <pose>0 0 0 0 -0 0</pose>
          <geometry>
            <mesh>
              <scale>1 1 1</scale>
              <uri>model://rs_robot/meshes/DAE/roller/roller.dae</uri>
            </mesh>
          </geometry>
        </visual>
        <self_collide>0</self_collide>
        <enable_wind>0</enable_wind>
        <kinematic>0</kinematic>
      </link>
      <joint name='r1_F_roller_joint' type='revolute'>
        <pose relative_to='first_wheel_link'>0 -0.006 0.024063 0 -0 1.5708</pose>
        <parent>first_wheel_link</parent>
        <child>r1_F_roller_link</child>
        <axis>
          <xyz>0 1 0</xyz>
          <limit>
            <lower>-1e+16</lower>
            <upper>1e+16</upper>
          </limit>
          <dynamics>
            <spring_reference>0</spring_reference>
            <spring_stiffness>0</spring_stiffness>
          </dynamics>
        </axis>
      </joint>
      <link name='r1_F_roller_link'>
        <pose relative_to='r1_F_roller_joint'>0 0 0 0 -0 0</pose>
        <inertial>
          <pose>0 0 0 0 -0 0</pose>
          <mass>0.009</mass>
          <inertia>
            <ixx>1.257e-06</ixx>
            <ixy>0</ixy>
            <ixz>0</ixz>
            <iyy>3.42e-07</iyy>
            <iyz>0</iyz>
            <izz>1.257e-06</izz>
          </inertia>
        </inertial>
        <collision name='r1_F_roller_link_collision'>
          <pose>0 0 0 0 -0 0</pose>
          <geometry>
            <mesh>
              <scale>1 1 1</scale>
              <uri>model://rs_robot/meshes/STL/roller/roller.stl</uri>
            </mesh>
          </geometry>
          <surface>
            <contact>
              <ode>
                <max_vel>0.01</max_vel>
              </ode>
            </contact>
            <friction>
              <ode>
                <mu>1.5</mu>
                <mu2>1.5</mu2>
                <kp>1e15</kp>
                <kd>1e13</kd>
              </ode>
              <torsional>
                <ode/>
              </torsional>
            </friction>
            <bounce>
              <restitution_coefficient>0.01</restitution_coefficient>
              <threshold>0</threshold>
            </bounce>
          </surface>
          <max_contacts>10</max_contacts>
        </collision>
        <visual name='r1_F_roller_link_visual'>
          <pose>0 0 0 0 -0 0</pose>
          <geometry>
            <mesh>
              <scale>1 1 1</scale>
              <uri>model://rs_robot/meshes/DAE/roller/roller.dae</uri>
            </mesh>
          </geometry>
        </visual>
        <self_collide>0</self_collide>
        <enable_wind>0</enable_wind>
        <kinematic>0</kinematic>
      </link>
      <joint name='r2_F_roller_joint' type='revolute'>
        <pose relative_to='first_wheel_link'>-0.022885 -0.006 0.007436 -1.25664 0 1.5708</pose>
        <parent>first_wheel_link</parent>
        <child>r2_F_roller_link</child>
        <axis>
          <xyz>0 1 0</xyz>
          <limit>
            <lower>-1e+16</lower>
            <upper>1e+16</upper>
          </limit>
          <dynamics>
            <spring_reference>0</spring_reference>
            <spring_stiffness>0</spring_stiffness>
          </dynamics>
        </axis>
      </joint>
      <link name='r2_F_roller_link'>
        <pose relative_to='r2_F_roller_joint'>0 0 0 0 -0 0</pose>
        <inertial>
          <pose>0 0 0 0 -0 0</pose>
          <mass>0.009</mass>
          <inertia>
            <ixx>1.257e-06</ixx>
            <ixy>0</ixy>
            <ixz>0</ixz>
            <iyy>3.42e-07</iyy>
            <iyz>0</iyz>
            <izz>1.257e-06</izz>
          </inertia>
        </inertial>
        <collision name='r2_F_roller_link_collision'>
          <pose>0 0 0 0 -0 0</pose>
          <geometry>
            <mesh>
              <scale>1 1 1</scale>
              <uri>model://rs_robot/meshes/STL/roller/roller.stl</uri>
            </mesh>
          </geometry>
          <surface>
            <contact>
              <ode>
                <max_vel>0.01</max_vel>
              </ode>
            </contact>
            <friction>
              <ode>
                <mu>1.5</mu>
                <mu2>1.5</mu2>
                <kp>1e15</kp>
                <kd>1e13</kd>
              </ode>
              <torsional>
                <ode/>
              </torsional>
            </friction>
            <bounce>
              <restitution_coefficient>0.01</restitution_coefficient>
              <threshold>0</threshold>
            </bounce>
          </surface>
          <max_contacts>10</max_contacts>
        </collision>
        <visual name='r2_F_roller_link_visual'>
          <pose>0 0 0 0 -0 0</pose>
          <geometry>
            <mesh>
              <scale>1 1 1</scale>
              <uri>model://rs_robot/meshes/DAE/roller/roller.dae</uri>
            </mesh>
          </geometry>
        </visual>
        <self_collide>0</self_collide>
        <enable_wind>0</enable_wind>
        <kinematic>0</kinematic>
      </link>
      <joint name='r3_F_roller_joint' type='revolute'>
        <pose relative_to='first_wheel_link'>-0.014144 -0.006 -0.019467 -2.51327 -0 1.5708</pose>
        <parent>first_wheel_link</parent>
        <child>r3_F_roller_link</child>
        <axis>
          <xyz>0 1 0</xyz>
          <limit>
            <lower>-1e+16</lower>
            <upper>1e+16</upper>
          </limit>
          <dynamics>
            <spring_reference>0</spring_reference>
            <spring_stiffness>0</spring_stiffness>
          </dynamics>
        </axis>
      </joint>
      <link name='r3_F_roller_link'>
        <pose relative_to='r3_F_roller_joint'>0 0 0 0 -0 0</pose>
        <inertial>
          <pose>0 0 0 0 -0 0</pose>
          <mass>0.009</mass>
          <inertia>
            <ixx>1.257e-06</ixx>
            <ixy>0</ixy>
            <ixz>0</ixz>
            <iyy>3.42e-07</iyy>
            <iyz>0</iyz>
            <izz>1.257e-06</izz>
          </inertia>
        </inertial>
        <collision name='r3_F_roller_link_collision'>
          <pose>0 0 0 0 -0 0</pose>
          <geometry>
            <mesh>
              <scale>1 1 1</scale>
              <uri>model://rs_robot/meshes/STL/roller/roller.stl</uri>
            </mesh>
          </geometry>
          <surface>
            <contact>
              <ode>
                <max_vel>0.01</max_vel>
              </ode>
            </contact>
            <friction>
              <ode>
                <mu>1.5</mu>
                <mu2>1.5</mu2>
                <kp>1e15</kp>
                <kd>1e13</kd>
              </ode>
              <torsional>
                <ode/>
              </torsional>
            </friction>
            <bounce>
              <restitution_coefficient>0.01</restitution_coefficient>
              <threshold>0</threshold>
            </bounce>
          </surface>
          <max_contacts>10</max_contacts>
        </collision>
        <visual name='r3_F_roller_link_visual'>
          <pose>0 0 0 0 -0 0</pose>
          <geometry>
            <mesh>
              <scale>1 1 1</scale>
              <uri>model://rs_robot/meshes/DAE/roller/roller.dae</uri>
            </mesh>
          </geometry>
        </visual>
        <self_collide>0</self_collide>
        <enable_wind>0</enable_wind>
        <kinematic>0</kinematic>
      </link>
      <joint name='r4_F_roller_joint' type='revolute'>
        <pose relative_to='first_wheel_link'>0.014144 -0.006 -0.019467 2.51327 -0 1.5708</pose>
        <parent>first_wheel_link</parent>
        <child>r4_F_roller_link</child>
        <axis>
          <xyz>0 1 0</xyz>
          <limit>
            <lower>-1e+16</lower>
            <upper>1e+16</upper>
          </limit>
          <dynamics>
            <spring_reference>0</spring_reference>
            <spring_stiffness>0</spring_stiffness>
          </dynamics>
        </axis>
      </joint>
      <link name='r4_F_roller_link'>
        <pose relative_to='r4_F_roller_joint'>0 0 0 0 -0 0</pose>
        <inertial>
          <pose>0 0 0 0 -0 0</pose>
          <mass>0.009</mass>
          <inertia>
            <ixx>1.257e-06</ixx>
            <ixy>0</ixy>
            <ixz>0</ixz>
            <iyy>3.42e-07</iyy>
            <iyz>0</iyz>
            <izz>1.257e-06</izz>
          </inertia>
        </inertial>
        <collision name='r4_F_roller_link_collision'>
          <pose>0 0 0 0 -0 0</pose>
          <geometry>
            <mesh>
              <scale>1 1 1</scale>
              <uri>model://rs_robot/meshes/STL/roller/roller.stl</uri>
            </mesh>
            <surface>
              <contact>
                <ode>
                  <max_vel>0.01</max_vel>
                </ode>
              </contact>
              <friction>
                <ode>
                  <mu>1.5</mu>
                  <mu2>1.5</mu2>
                  <kp>1e15</kp>
                  <kd>1e13</kd>
                </ode>
              </friction>
              <bounce>
                <restitution_coefficient>0.01</restitution_coefficient>
                <threshold>0</threshold>
              </bounce>
            </surface>
          </geometry>
          <max_contacts>10</max_contacts>
          <surface>
            <contact>
              <ode/>
            </contact>
            <bounce/>
            <friction>
              <torsional>
                <ode/>
              </torsional>
              <ode/>
            </friction>
          </surface>
        </collision>
        <visual name='r4_F_roller_link_visual'>
          <pose>0 0 0 0 -0 0</pose>
          <geometry>
            <mesh>
              <scale>1 1 1</scale>
              <uri>model://rs_robot/meshes/DAE/roller/roller.dae</uri>
            </mesh>
          </geometry>
        </visual>
        <self_collide>0</self_collide>
        <enable_wind>0</enable_wind>
        <kinematic>0</kinematic>
      </link>
      <joint name='r5_F_roller_joint' type='revolute'>
        <pose relative_to='first_wheel_link'>0.022885 -0.006 0.007436 1.25664 -0 1.5708</pose>
        <parent>first_wheel_link</parent>
        <child>r5_F_roller_link</child>
        <axis>
          <xyz>0 1 0</xyz>
          <limit>
            <lower>-1e+16</lower>
            <upper>1e+16</upper>
          </limit>
          <dynamics>
            <spring_reference>0</spring_reference>
            <spring_stiffness>0</spring_stiffness>
          </dynamics>
        </axis>
      </joint>
      <link name='r5_F_roller_link'>
        <pose relative_to='r5_F_roller_joint'>0 0 0 0 -0 0</pose>
        <inertial>
          <pose>0 0 0 0 -0 0</pose>
          <mass>0.009</mass>
          <inertia>
            <ixx>1.257e-06</ixx>
            <ixy>0</ixy>
            <ixz>0</ixz>
            <iyy>3.42e-07</iyy>
            <iyz>0</iyz>
            <izz>1.257e-06</izz>
          </inertia>
        </inertial>
        <collision name='r5_F_roller_link_collision'>
          <pose>0 0 0 0 -0 0</pose>
          <geometry>
            <mesh>
              <scale>1 1 1</scale>
              <uri>model://rs_robot/meshes/STL/roller/roller.stl</uri>
            </mesh>
          </geometry>
          <surface>
            <contact>
              <ode>
                <max_vel>0.01</max_vel>
              </ode>
            </contact>
            <friction>
              <ode>
                <mu>1.5</mu>
                <mu2>1.5</mu2>
                <kp>1e15</kp>
                <kd>1e13</kd>
              </ode>
              <torsional>
                <ode/>
              </torsional>
            </friction>
            <bounce>
              <restitution_coefficient>0.01</restitution_coefficient>
              <threshold>0</threshold>
            </bounce>
          </surface>
          <max_contacts>10</max_contacts>
        </collision>
        <visual name='r5_F_roller_link_visual'>
          <pose>0 0 0 0 -0 0</pose>
          <geometry>
            <mesh>
              <scale>1 1 1</scale>
              <uri>model://rs_robot/meshes/DAE/roller/roller.dae</uri>
            </mesh>
          </geometry>
        </visual>
        <self_collide>0</self_collide>
        <enable_wind>0</enable_wind>
        <kinematic>0</kinematic>
      </link>
      <joint name='r6_F_roller_joint' type='revolute'>
        <pose relative_to='first_wheel_link'>0 0.006 -0.024063 0 -0 1.5708</pose>
        <parent>first_wheel_link</parent>
        <child>r6_F_roller_link</child>
        <axis>
          <xyz>0 1 0</xyz>
          <limit>
            <lower>-1e+16</lower>
            <upper>1e+16</upper>
          </limit>
          <dynamics>
            <spring_reference>0</spring_reference>
            <spring_stiffness>0</spring_stiffness>
          </dynamics>
        </axis>
      </joint>
      <link name='r6_F_roller_link'>
        <pose relative_to='r6_F_roller_joint'>0 0 0 0 -0 0</pose>
        <inertial>
          <pose>0 0 0 0 -0 0</pose>
          <mass>0.009</mass>
          <inertia>
            <ixx>1.257e-06</ixx>
            <ixy>0</ixy>
            <ixz>0</ixz>
            <iyy>3.42e-07</iyy>
            <iyz>0</iyz>
            <izz>1.257e-06</izz>
          </inertia>
        </inertial>
        <collision name='r6_F_roller_link_collision'>
          <pose>0 0 0 0 -0 0</pose>
          <geometry>
            <mesh>
              <scale>1 1 1</scale>
              <uri>model://rs_robot/meshes/STL/roller/roller.stl</uri>
            </mesh>
          </geometry>
          <surface>
            <contact>
              <ode>
                <max_vel>0.01</max_vel>
              </ode>
            </contact>
            <friction>
              <ode>
                <mu>1.5</mu>
                <mu2>1.5</mu2>
                <kp>1e15</kp>
                <kd>1e13</kd>
              </ode>
              <torsional>
                <ode/>
              </torsional>
            </friction>
            <bounce>
              <restitution_coefficient>0.01</restitution_coefficient>
              <threshold>0</threshold>
            </bounce>
          </surface>
          <max_contacts>10</max_contacts>
        </collision>
        <visual name='r6_F_roller_link_visual'>
          <pose>0 0 0 0 -0 0</pose>
          <geometry>
            <mesh>
              <scale>1 1 1</scale>
              <uri>model://rs_robot/meshes/DAE/roller/roller.dae</uri>
            </mesh>
          </geometry>
        </visual>
        <self_collide>0</self_collide>
        <enable_wind>0</enable_wind>
        <kinematic>0</kinematic>
      </link>
      <joint name='r7_F_roller_joint' type='revolute'>
        <pose relative_to='first_wheel_link'>0.022885 0.006 -0.007436 -1.25664 0 1.5708</pose>
        <parent>first_wheel_link</parent>
        <child>r7_F_roller_link</child>
        <axis>
          <xyz>0 1 0</xyz>
          <limit>
            <lower>-1e+16</lower>
            <upper>1e+16</upper>
          </limit>
          <dynamics>
            <spring_reference>0</spring_reference>
            <spring_stiffness>0</spring_stiffness>
          </dynamics>
        </axis>
      </joint>
      <link name='r7_F_roller_link'>
        <pose relative_to='r7_F_roller_joint'>0 0 0 0 -0 0</pose>
        <inertial>
          <pose>0 0 0 0 -0 0</pose>
          <mass>0.009</mass>
          <inertia>
            <ixx>1.257e-06</ixx>
            <ixy>0</ixy>
            <ixz>0</ixz>
            <iyy>3.42e-07</iyy>
            <iyz>0</iyz>
            <izz>1.257e-06</izz>
          </inertia>
        </inertial>
        <collision name='r7_F_roller_link_collision'>
          <pose>0 0 0 0 -0 0</pose>
          <geometry>
            <mesh>
              <scale>1 1 1</scale>
              <uri>model://rs_robot/meshes/STL/roller/roller.stl</uri>
            </mesh>
          </geometry>
          <surface>
            <contact>
              <ode>
                <max_vel>0.01</max_vel>
              </ode>
            </contact>
            <friction>
              <ode>
                <mu>1.5</mu>
                <mu2>1.5</mu2>
                <kp>1e15</kp>
                <kd>1e13</kd>
              </ode>
              <torsional>
                <ode/>
              </torsional>
            </friction>
            <bounce>
              <restitution_coefficient>0.01</restitution_coefficient>
              <threshold>0</threshold>
            </bounce>
          </surface>
          <max_contacts>10</max_contacts>
        </collision>
        <visual name='r7_F_roller_link_visual'>
          <pose>0 0 0 0 -0 0</pose>
          <geometry>
            <mesh>
              <scale>1 1 1</scale>
              <uri>model://rs_robot/meshes/DAE/roller/roller.dae</uri>
            </mesh>
          </geometry>
        </visual>
        <self_collide>0</self_collide>
        <enable_wind>0</enable_wind>
        <kinematic>0</kinematic>
      </link>
      <joint name='r8_F_roller_joint' type='revolute'>
        <pose relative_to='first_wheel_link'>0.014144 0.006 0.019467 -2.51327 -0 1.5708</pose>
        <parent>first_wheel_link</parent>
        <child>r8_F_roller_link</child>
        <axis>
          <xyz>0 1 0</xyz>
          <limit>
            <lower>-1e+16</lower>
            <upper>1e+16</upper>
          </limit>
          <dynamics>
            <spring_reference>0</spring_reference>
            <spring_stiffness>0</spring_stiffness>
          </dynamics>
        </axis>
      </joint>
      <link name='r8_F_roller_link'>
        <pose relative_to='r8_F_roller_joint'>0 0 0 0 -0 0</pose>
        <inertial>
          <pose>0 0 0 0 -0 0</pose>
          <mass>0.009</mass>
          <inertia>
            <ixx>1.257e-06</ixx>
            <ixy>0</ixy>
            <ixz>0</ixz>
            <iyy>3.42e-07</iyy>
            <iyz>0</iyz>
            <izz>1.257e-06</izz>
          </inertia>
        </inertial>
        <collision name='r8_F_roller_link_collision'>
          <pose>0 0 0 0 -0 0</pose>
          <geometry>
            <mesh>
              <scale>1 1 1</scale>
              <uri>model://rs_robot/meshes/STL/roller/roller.stl</uri>
            </mesh>
          </geometry>
          <surface>
            <contact>
              <ode>
                <max_vel>0.01</max_vel>
              </ode>
            </contact>
            <friction>
              <ode>
                <mu>1.5</mu>
                <mu2>1.5</mu2>
                <kp>1e15</kp>
                <kd>1e13</kd>
              </ode>
              <torsional>
                <ode/>
              </torsional>
            </friction>
            <bounce>
              <restitution_coefficient>0.01</restitution_coefficient>
              <threshold>0</threshold>
            </bounce>
          </surface>
          <max_contacts>10</max_contacts>
        </collision>
        <visual name='r8_F_roller_link_visual'>
          <pose>0 0 0 0 -0 0</pose>
          <geometry>
            <mesh>
              <scale>1 1 1</scale>
              <uri>model://rs_robot/meshes/DAE/roller/roller.dae</uri>
            </mesh>
          </geometry>
        </visual>
        <self_collide>0</self_collide>
        <enable_wind>0</enable_wind>
        <kinematic>0</kinematic>
      </link>
      <joint name='r9_F_roller_joint' type='revolute'>
        <pose relative_to='first_wheel_link'>-0.014144 0.006 0.019467 2.51327 -0 1.5708</pose>
        <parent>first_wheel_link</parent>
        <child>r9_F_roller_link</child>
        <axis>
          <xyz>0 1 0</xyz>
          <limit>
            <lower>-1e+16</lower>
            <upper>1e+16</upper>
          </limit>
          <dynamics>
            <spring_reference>0</spring_reference>
            <spring_stiffness>0</spring_stiffness>
          </dynamics>
        </axis>
      </joint>
      <link name='r9_F_roller_link'>
        <pose relative_to='r9_F_roller_joint'>0 0 0 0 -0 0</pose>
        <inertial>
          <pose>0 0 0 0 -0 0</pose>
          <mass>0.009</mass>
          <inertia>
            <ixx>1.257e-06</ixx>
            <ixy>0</ixy>
            <ixz>0</ixz>
            <iyy>3.42e-07</iyy>
            <iyz>0</iyz>
            <izz>1.257e-06</izz>
          </inertia>
        </inertial>
        <collision name='r9_F_roller_link_collision'>
          <pose>0 0 0 0 -0 0</pose>
          <geometry>
            <mesh>
              <scale>1 1 1</scale>
              <uri>model://rs_robot/meshes/STL/roller/roller.stl</uri>
            </mesh>
          </geometry>
          <surface>
            <contact>
              <ode>
                <max_vel>0.01</max_vel>
              </ode>
            </contact>
            <friction>
              <ode>
                <mu>1.5</mu>
                <mu2>1.5</mu2>
                <kp>1e15</kp>
                <kd>1e13</kd>
              </ode>
              <torsional>
                <ode/>
              </torsional>
            </friction>
            <bounce>
              <restitution_coefficient>0.01</restitution_coefficient>
              <threshold>0</threshold>
            </bounce>
          </surface>
          <max_contacts>10</max_contacts>
        </collision>
        <visual name='r9_F_roller_link_visual'>
          <pose>0 0 0 0 -0 0</pose>
          <geometry>
            <mesh>
              <scale>1 1 1</scale>
              <uri>model://rs_robot/meshes/DAE/roller/roller.dae</uri>
            </mesh>
          </geometry>
        </visual>
        <self_collide>0</self_collide>
        <enable_wind>0</enable_wind>
        <kinematic>0</kinematic>
      </link>
      <joint name='fourth_wheel_joint' type='revolute'>
        <pose relative_to='base_link'>-0.086338 -0.086338 -0.022 0 -0 2.3562</pose>
        <parent>base_link</parent>
        <child>fourth_wheel_link</child>
        <axis>
          <xyz>0 1 0</xyz>
          <limit>
            <effort>100</effort>
            <velocity>100</velocity>
            <lower>-1e+16</lower>
            <upper>1e+16</upper>
          </limit>
          <dynamics>
            <spring_reference>0</spring_reference>
            <spring_stiffness>0</spring_stiffness>
          </dynamics>
        </axis>
      </joint>
      <link name='fourth_wheel_link'>
        <pose relative_to='fourth_wheel_joint'>0 0 0 0 -0 0</pose>
        <inertial>
          <pose>0 -0.011 0 0 -0 0</pose>
          <mass>0.25</mass>
          <inertia>
            <ixx>0.00031</ixx>
            <ixy>0</ixy>
            <ixz>0</ixz>
            <iyy>0.0005</iyy>
            <iyz>0</iyz>
            <izz>0.00031</izz>
          </inertia>
        </inertial>
        <collision name='fourth_wheel_link_collision'>
          <pose>0 0 0 0 -0 0</pose>
          <geometry>
            <mesh>
              <scale>1 1 1</scale>
              <uri>model://rs_robot/meshes/STL/omni_wheel/omni_wheel.stl</uri>
            </mesh>
          </geometry>
          <surface>
            <contact>
              <ode>
                <max_vel>0.01</max_vel>
              </ode>
            </contact>
            <friction>
              <ode>
                <mu>1.5</mu>
                <mu2>1.5</mu2>
                <kp>1e15</kp>
                <kd>1e13</kd>
              </ode>
              <torsional>
                <ode/>
              </torsional>
            </friction>
            <bounce>
              <restitution_coefficient>0.01</restitution_coefficient>
              <threshold>0</threshold>
            </bounce>
          </surface>
          <max_contacts>10</max_contacts>
        </collision>
        <visual name='fourth_wheel_link_visual'>
          <pose>0 0 0 0 -0 0</pose>
          <geometry>
            <mesh>
              <scale>1 1 1</scale>
              <uri>model://rs_robot/meshes/DAE/omni_wheel/omni_wheel.dae</uri>
            </mesh>
          </geometry>
        </visual>
        <self_collide>0</self_collide>
        <enable_wind>0</enable_wind>
        <kinematic>0</kinematic>
      </link>
      <joint name='r10_R_roller_joint' type='revolute'>
        <pose relative_to='fourth_wheel_link'>-0.022885 0.006 -0.007436 1.25664 -0 1.5708</pose>
        <parent>fourth_wheel_link</parent>
        <child>r10_R_roller_link</child>
        <axis>
          <xyz>0 1 0</xyz>
          <limit>
            <lower>-1e+16</lower>
            <upper>1e+16</upper>
          </limit>
          <dynamics>
            <spring_reference>0</spring_reference>
            <spring_stiffness>0</spring_stiffness>
          </dynamics>
        </axis>
      </joint>
      <link name='r10_R_roller_link'>
        <pose relative_to='r10_R_roller_joint'>0 0 0 0 -0 0</pose>
        <inertial>
          <pose>0 0 0 0 -0 0</pose>
          <mass>0.009</mass>
          <inertia>
            <ixx>1.257e-06</ixx>
            <ixy>0</ixy>
            <ixz>0</ixz>
            <iyy>3.42e-07</iyy>
            <iyz>0</iyz>
            <izz>1.257e-06</izz>
          </inertia>
        </inertial>
        <collision name='r10_R_roller_link_collision'>
          <pose>0 0 0 0 -0 0</pose>
          <geometry>
            <mesh>
              <scale>1 1 1</scale>
              <uri>model://rs_robot/meshes/STL/roller/roller.stl</uri>
            </mesh>
          </geometry>
          <surface>
            <contact>
              <ode>
                <max_vel>0.01</max_vel>
              </ode>
            </contact>
            <friction>
              <ode>
                <mu>1.5</mu>
                <mu2>1.5</mu2>
                <kp>1e15</kp>
                <kd>1e13</kd>
              </ode>
              <torsional>
                <ode/>
              </torsional>
            </friction>
            <bounce>
              <restitution_coefficient>0.01</restitution_coefficient>
              <threshold>0</threshold>
            </bounce>
          </surface>
          <max_contacts>10</max_contacts>
        </collision>
        <visual name='r10_R_roller_link_visual'>
          <pose>0 0 0 0 -0 0</pose>
          <geometry>
            <mesh>
              <scale>1 1 1</scale>
              <uri>model://rs_robot/meshes/DAE/roller/roller.dae</uri>
            </mesh>
          </geometry>
        </visual>
        <self_collide>0</self_collide>
        <enable_wind>0</enable_wind>
        <kinematic>0</kinematic>
      </link>
      <joint name='r1_R_roller_joint' type='revolute'>
        <pose relative_to='fourth_wheel_link'>0 -0.006 0.024063 0 -0 1.5708</pose>
        <parent>fourth_wheel_link</parent>
        <child>r1_R_roller_link</child>
        <axis>
          <xyz>0 1 0</xyz>
          <limit>
            <lower>-1e+16</lower>
            <upper>1e+16</upper>
          </limit>
          <dynamics>
            <spring_reference>0</spring_reference>
            <spring_stiffness>0</spring_stiffness>
          </dynamics>
        </axis>
      </joint>
      <link name='r1_R_roller_link'>
        <pose relative_to='r1_R_roller_joint'>0 0 0 0 -0 0</pose>
        <inertial>
          <pose>0 0 0 0 -0 0</pose>
          <mass>0.009</mass>
          <inertia>
            <ixx>1.257e-06</ixx>
            <ixy>0</ixy>
            <ixz>0</ixz>
            <iyy>3.42e-07</iyy>
            <iyz>0</iyz>
            <izz>1.257e-06</izz>
          </inertia>
        </inertial>
        <collision name='r1_R_roller_link_collision'>
          <pose>0 0 0 0 -0 0</pose>
          <geometry>
            <mesh>
              <scale>1 1 1</scale>
              <uri>model://rs_robot/meshes/STL/roller/roller.stl</uri>
            </mesh>
          </geometry>
          <surface>
            <contact>
              <ode>
                <max_vel>0.01</max_vel>
              </ode>
            </contact>
            <friction>
              <ode>
                <mu>1.5</mu>
                <mu2>1.5</mu2>
                <kp>1e15</kp>
                <kd>1e13</kd>
              </ode>
              <torsional>
                <ode/>
              </torsional>
            </friction>
            <bounce>
              <restitution_coefficient>0.01</restitution_coefficient>
              <threshold>0</threshold>
            </bounce>
          </surface>
          <max_contacts>10</max_contacts>
        </collision>
        <visual name='r1_R_roller_link_visual'>
          <pose>0 0 0 0 -0 0</pose>
          <geometry>
            <mesh>
              <scale>1 1 1</scale>
              <uri>model://rs_robot/meshes/DAE/roller/roller.dae</uri>
            </mesh>
          </geometry>
        </visual>
        <self_collide>0</self_collide>
        <enable_wind>0</enable_wind>
        <kinematic>0</kinematic>
      </link>
      <joint name='r2_R_roller_joint' type='revolute'>
        <pose relative_to='fourth_wheel_link'>-0.022885 -0.006 0.007436 -1.25664 0 1.5708</pose>
        <parent>fourth_wheel_link</parent>
        <child>r2_R_roller_link</child>
        <axis>
          <xyz>0 1 0</xyz>
          <limit>
            <lower>-1e+16</lower>
            <upper>1e+16</upper>
          </limit>
          <dynamics>
            <spring_reference>0</spring_reference>
            <spring_stiffness>0</spring_stiffness>
          </dynamics>
        </axis>
      </joint>
      <link name='r2_R_roller_link'>
        <pose relative_to='r2_R_roller_joint'>0 0 0 0 -0 0</pose>
        <inertial>
          <pose>0 0 0 0 -0 0</pose>
          <mass>0.009</mass>
          <inertia>
            <ixx>1.257e-06</ixx>
            <ixy>0</ixy>
            <ixz>0</ixz>
            <iyy>3.42e-07</iyy>
            <iyz>0</iyz>
            <izz>1.257e-06</izz>
          </inertia>
        </inertial>
        <collision name='r2_R_roller_link_collision'>
          <pose>0 0 0 0 -0 0</pose>
          <geometry>
            <mesh>
              <scale>1 1 1</scale>
              <uri>model://rs_robot/meshes/STL/roller/roller.stl</uri>
            </mesh>
          </geometry>
          <surface>
            <contact>
              <ode>
                <max_vel>0.01</max_vel>
              </ode>
            </contact>
            <friction>
              <ode>
                <mu>1.5</mu>
                <mu2>1.5</mu2>
                <kp>1e15</kp>
                <kd>1e13</kd>
              </ode>
              <torsional>
                <ode/>
              </torsional>
            </friction>
            <bounce>
              <restitution_coefficient>0.01</restitution_coefficient>
              <threshold>0</threshold>
            </bounce>
          </surface>
          <max_contacts>10</max_contacts>
        </collision>
        <visual name='r2_R_roller_link_visual'>
          <pose>0 0 0 0 -0 0</pose>
          <geometry>
            <mesh>
              <scale>1 1 1</scale>
              <uri>model://rs_robot/meshes/DAE/roller/roller.dae</uri>
            </mesh>
          </geometry>
        </visual>
        <self_collide>0</self_collide>
        <enable_wind>0</enable_wind>
        <kinematic>0</kinematic>
      </link>
      <joint name='r3_R_roller_joint' type='revolute'>
        <pose relative_to='fourth_wheel_link'>-0.014144 -0.006 -0.019467 -2.51327 -0 1.5708</pose>
        <parent>fourth_wheel_link</parent>
        <child>r3_R_roller_link</child>
        <axis>
          <xyz>0 1 0</xyz>
          <limit>
            <lower>-1e+16</lower>
            <upper>1e+16</upper>
          </limit>
          <dynamics>
            <spring_reference>0</spring_reference>
            <spring_stiffness>0</spring_stiffness>
          </dynamics>
        </axis>
      </joint>
      <link name='r3_R_roller_link'>
        <pose relative_to='r3_R_roller_joint'>0 0 0 0 -0 0</pose>
        <inertial>
          <pose>0 0 0 0 -0 0</pose>
          <mass>0.009</mass>
          <inertia>
            <ixx>1.257e-06</ixx>
            <ixy>0</ixy>
            <ixz>0</ixz>
            <iyy>3.42e-07</iyy>
            <iyz>0</iyz>
            <izz>1.257e-06</izz>
          </inertia>
        </inertial>
        <collision name='r3_R_roller_link_collision'>
          <pose>0 0 0 0 -0 0</pose>
          <geometry>
            <mesh>
              <scale>1 1 1</scale>
              <uri>model://rs_robot/meshes/STL/roller/roller.stl</uri>
            </mesh>
          </geometry>
          <surface>
            <contact>
              <ode>
                <max_vel>0.01</max_vel>
              </ode>
            </contact>
            <friction>
              <ode>
                <mu>1.5</mu>
                <mu2>1.5</mu2>
                <kp>1e15</kp>
                <kd>1e13</kd>
              </ode>
              <torsional>
                <ode/>
              </torsional>
            </friction>
            <bounce>
              <restitution_coefficient>0.01</restitution_coefficient>
              <threshold>0</threshold>
            </bounce>
          </surface>
          <max_contacts>10</max_contacts>
        </collision>
        <visual name='r3_R_roller_link_visual'>
          <pose>0 0 0 0 -0 0</pose>
          <geometry>
            <mesh>
              <scale>1 1 1</scale>
              <uri>model://rs_robot/meshes/DAE/roller/roller.dae</uri>
            </mesh>
          </geometry>
        </visual>
        <self_collide>0</self_collide>
        <enable_wind>0</enable_wind>
        <kinematic>0</kinematic>
      </link>
      <joint name='r4_R_roller_joint' type='revolute'>
        <pose relative_to='fourth_wheel_link'>0.014144 -0.006 -0.019467 2.51327 -0 1.5708</pose>
        <parent>fourth_wheel_link</parent>
        <child>r4_R_roller_link</child>
        <axis>
          <xyz>0 1 0</xyz>
          <limit>
            <lower>-1e+16</lower>
            <upper>1e+16</upper>
          </limit>
          <dynamics>
            <spring_reference>0</spring_reference>
            <spring_stiffness>0</spring_stiffness>
          </dynamics>
        </axis>
      </joint>
      <link name='r4_R_roller_link'>
        <pose relative_to='r4_R_roller_joint'>0 0 0 0 -0 0</pose>
        <inertial>
          <pose>0 0 0 0 -0 0</pose>
          <mass>0.009</mass>
          <inertia>
            <ixx>1.257e-06</ixx>
            <ixy>0</ixy>
            <ixz>0</ixz>
            <iyy>3.42e-07</iyy>
            <iyz>0</iyz>
            <izz>1.257e-06</izz>
          </inertia>
        </inertial>
        <collision name='r4_R_roller_link_collision'>
          <pose>0 0 0 0 -0 0</pose>
          <geometry>
            <mesh>
              <scale>1 1 1</scale>
              <uri>model://rs_robot/meshes/STL/roller/roller.stl</uri>
            </mesh>
          </geometry>
          <surface>
            <contact>
              <ode>
                <max_vel>0.01</max_vel>
              </ode>
            </contact>
            <friction>
              <ode>
                <mu>1.5</mu>
                <mu2>1.5</mu2>
                <kp>1e15</kp>
                <kd>1e13</kd>
              </ode>
              <torsional>
                <ode/>
              </torsional>
            </friction>
            <bounce>
              <restitution_coefficient>0.01</restitution_coefficient>
              <threshold>0</threshold>
            </bounce>
          </surface>
          <max_contacts>10</max_contacts>
        </collision>
        <visual name='r4_R_roller_link_visual'>
          <pose>0 0 0 0 -0 0</pose>
          <geometry>
            <mesh>
              <scale>1 1 1</scale>
              <uri>model://rs_robot/meshes/DAE/roller/roller.dae</uri>
            </mesh>
          </geometry>
        </visual>
        <self_collide>0</self_collide>
        <enable_wind>0</enable_wind>
        <kinematic>0</kinematic>
      </link>
      <joint name='r5_R_roller_joint' type='revolute'>
        <pose relative_to='fourth_wheel_link'>0.022885 -0.006 0.007436 1.25664 -0 1.5708</pose>
        <parent>fourth_wheel_link</parent>
        <child>r5_R_roller_link</child>
        <axis>
          <xyz>0 1 0</xyz>
          <limit>
            <lower>-1e+16</lower>
            <upper>1e+16</upper>
          </limit>
          <dynamics>
            <spring_reference>0</spring_reference>
            <spring_stiffness>0</spring_stiffness>
          </dynamics>
        </axis>
      </joint>
      <link name='r5_R_roller_link'>
        <pose relative_to='r5_R_roller_joint'>0 0 0 0 -0 0</pose>
        <inertial>
          <pose>0 0 0 0 -0 0</pose>
          <mass>0.009</mass>
          <inertia>
            <ixx>1.257e-06</ixx>
            <ixy>0</ixy>
            <ixz>0</ixz>
            <iyy>3.42e-07</iyy>
            <iyz>0</iyz>
            <izz>1.257e-06</izz>
          </inertia>
        </inertial>
        <collision name='r5_R_roller_link_collision'>
          <pose>0 0 0 0 -0 0</pose>
          <geometry>
            <mesh>
              <scale>1 1 1</scale>
              <uri>model://rs_robot/meshes/STL/roller/roller.stl</uri>
            </mesh>
          </geometry>
          <surface>
            <contact>
              <ode>
                <max_vel>0.01</max_vel>
              </ode>
            </contact>
            <friction>
              <ode>
                <mu>1.5</mu>
                <mu2>1.5</mu2>
                <kp>1e15</kp>
                <kd>1e13</kd>
              </ode>
              <torsional>
                <ode/>
              </torsional>
            </friction>
            <bounce>
              <restitution_coefficient>0.01</restitution_coefficient>
              <threshold>0</threshold>
            </bounce>
          </surface>
          <max_contacts>10</max_contacts>
        </collision>
        <visual name='r5_R_roller_link_visual'>
          <pose>0 0 0 0 -0 0</pose>
          <geometry>
            <mesh>
              <scale>1 1 1</scale>
              <uri>model://rs_robot/meshes/DAE/roller/roller.dae</uri>
            </mesh>
          </geometry>
        </visual>
        <self_collide>0</self_collide>
        <enable_wind>0</enable_wind>
        <kinematic>0</kinematic>
      </link>
      <joint name='r6_R_roller_joint' type='revolute'>
        <pose relative_to='fourth_wheel_link'>0 0.006 -0.024063 0 -0 1.5708</pose>
        <parent>fourth_wheel_link</parent>
        <child>r6_R_roller_link</child>
        <axis>
          <xyz>0 1 0</xyz>
          <limit>
            <lower>-1e+16</lower>
            <upper>1e+16</upper>
          </limit>
          <dynamics>
            <spring_reference>0</spring_reference>
            <spring_stiffness>0</spring_stiffness>
          </dynamics>
        </axis>
      </joint>
      <link name='r6_R_roller_link'>
        <pose relative_to='r6_R_roller_joint'>0 0 0 0 -0 0</pose>
        <inertial>
          <pose>0 0 0 0 -0 0</pose>
          <mass>0.009</mass>
          <inertia>
            <ixx>1.257e-06</ixx>
            <ixy>0</ixy>
            <ixz>0</ixz>
            <iyy>3.42e-07</iyy>
            <iyz>0</iyz>
            <izz>1.257e-06</izz>
          </inertia>
        </inertial>
        <collision name='r6_R_roller_link_collision'>
          <pose>0 0 0 0 -0 0</pose>
          <geometry>
            <mesh>
              <scale>1 1 1</scale>
              <uri>model://rs_robot/meshes/STL/roller/roller.stl</uri>
            </mesh>
          </geometry>
          <surface>
            <contact>
              <ode>
                <max_vel>0.01</max_vel>
              </ode>
            </contact>
            <friction>
              <ode>
                <mu>1.5</mu>
                <mu2>1.5</mu2>
                <kp>1e15</kp>
                <kd>1e13</kd>
              </ode>
              <torsional>
                <ode/>
              </torsional>
            </friction>
            <bounce>
              <restitution_coefficient>0.01</restitution_coefficient>
              <threshold>0</threshold>
            </bounce>
          </surface>
          <max_contacts>10</max_contacts>
        </collision>
        <visual name='r6_R_roller_link_visual'>
          <pose>0 0 0 0 -0 0</pose>
          <geometry>
            <mesh>
              <scale>1 1 1</scale>
              <uri>model://rs_robot/meshes/DAE/roller/roller.dae</uri>
            </mesh>
          </geometry>
        </visual>
        <self_collide>0</self_collide>
        <enable_wind>0</enable_wind>
        <kinematic>0</kinematic>
      </link>
      <joint name='r7_R_roller_joint' type='revolute'>
        <pose relative_to='fourth_wheel_link'>0.022885 0.006 -0.007436 -1.25664 0 1.5708</pose>
        <parent>fourth_wheel_link</parent>
        <child>r7_R_roller_link</child>
        <axis>
          <xyz>0 1 0</xyz>
          <limit>
            <lower>-1e+16</lower>
            <upper>1e+16</upper>
          </limit>
          <dynamics>
            <spring_reference>0</spring_reference>
            <spring_stiffness>0</spring_stiffness>
          </dynamics>
        </axis>
      </joint>
      <link name='r7_R_roller_link'>
        <pose relative_to='r7_R_roller_joint'>0 0 0 0 -0 0</pose>
        <inertial>
          <pose>0 0 0 0 -0 0</pose>
          <mass>0.009</mass>
          <inertia>
            <ixx>1.257e-06</ixx>
            <ixy>0</ixy>
            <ixz>0</ixz>
            <iyy>3.42e-07</iyy>
            <iyz>0</iyz>
            <izz>1.257e-06</izz>
          </inertia>
        </inertial>
        <collision name='r7_R_roller_link_collision'>
          <pose>0 0 0 0 -0 0</pose>
          <geometry>
            <mesh>
              <scale>1 1 1</scale>
              <uri>model://rs_robot/meshes/STL/roller/roller.stl</uri>
            </mesh>
          </geometry>
          <surface>
            <contact>
              <ode>
                <max_vel>0.01</max_vel>
              </ode>
            </contact>
            <friction>
              <ode>
                <mu>1.5</mu>
                <mu2>1.5</mu2>
                <kp>1e15</kp>
                <kd>1e13</kd>
              </ode>
              <torsional>
                <ode/>
              </torsional>
            </friction>
            <bounce>
              <restitution_coefficient>0.01</restitution_coefficient>
              <threshold>0</threshold>
            </bounce>
          </surface>
          <max_contacts>10</max_contacts>
        </collision>
        <visual name='r7_R_roller_link_visual'>
          <pose>0 0 0 0 -0 0</pose>
          <geometry>
            <mesh>
              <scale>1 1 1</scale>
              <uri>model://rs_robot/meshes/DAE/roller/roller.dae</uri>
            </mesh>
          </geometry>
        </visual>
        <self_collide>0</self_collide>
        <enable_wind>0</enable_wind>
        <kinematic>0</kinematic>
      </link>
      <joint name='r8_R_roller_joint' type='revolute'>
        <pose relative_to='fourth_wheel_link'>0.014144 0.006 0.019467 -2.51327 -0 1.5708</pose>
        <parent>fourth_wheel_link</parent>
        <child>r8_R_roller_link</child>
        <axis>
          <xyz>0 1 0</xyz>
          <limit>
            <lower>-1e+16</lower>
            <upper>1e+16</upper>
          </limit>
          <dynamics>
            <spring_reference>0</spring_reference>
            <spring_stiffness>0</spring_stiffness>
          </dynamics>
        </axis>
      </joint>
      <link name='r8_R_roller_link'>
        <pose relative_to='r8_R_roller_joint'>0 0 0 0 -0 0</pose>
        <inertial>
          <pose>0 0 0 0 -0 0</pose>
          <mass>0.009</mass>
          <inertia>
            <ixx>1.257e-06</ixx>
            <ixy>0</ixy>
            <ixz>0</ixz>
            <iyy>3.42e-07</iyy>
            <iyz>0</iyz>
            <izz>1.257e-06</izz>
          </inertia>
        </inertial>
        <collision name='r8_R_roller_link_collision'>
          <pose>0 0 0 0 -0 0</pose>
          <geometry>
            <mesh>
              <scale>1 1 1</scale>
              <uri>model://rs_robot/meshes/STL/roller/roller.stl</uri>
            </mesh>
          </geometry>
          <surface>
            <contact>
              <ode>
                <max_vel>0.01</max_vel>
              </ode>
            </contact>
            <friction>
              <ode>
                <mu>1.5</mu>
                <mu2>1.5</mu2>
                <kp>1e15</kp>
                <kd>1e13</kd>
              </ode>
              <torsional>
                <ode/>
              </torsional>
            </friction>
            <bounce>
              <restitution_coefficient>0.01</restitution_coefficient>
              <threshold>0</threshold>
            </bounce>
          </surface>
          <max_contacts>10</max_contacts>
        </collision>
        <visual name='r8_R_roller_link_visual'>
          <pose>0 0 0 0 -0 0</pose>
          <geometry>
            <mesh>
              <scale>1 1 1</scale>
              <uri>model://rs_robot/meshes/DAE/roller/roller.dae</uri>
            </mesh>
          </geometry>
        </visual>
        <self_collide>0</self_collide>
        <enable_wind>0</enable_wind>
        <kinematic>0</kinematic>
      </link>
      <joint name='r9_R_roller_joint' type='revolute'>
        <pose relative_to='fourth_wheel_link'>-0.014144 0.006 0.019467 2.51327 -0 1.5708</pose>
        <parent>fourth_wheel_link</parent>
        <child>r9_R_roller_link</child>
        <axis>
          <xyz>0 1 0</xyz>
          <limit>
            <lower>-1e+16</lower>
            <upper>1e+16</upper>
          </limit>
          <dynamics>
            <spring_reference>0</spring_reference>
            <spring_stiffness>0</spring_stiffness>
          </dynamics>
        </axis>
      </joint>
      <link name='r9_R_roller_link'>
        <pose relative_to='r9_R_roller_joint'>0 0 0 0 -0 0</pose>
        <inertial>
          <pose>0 0 0 0 -0 0</pose>
          <mass>0.009</mass>
          <inertia>
            <ixx>1.257e-06</ixx>
            <ixy>0</ixy>
            <ixz>0</ixz>
            <iyy>3.42e-07</iyy>
            <iyz>0</iyz>
            <izz>1.257e-06</izz>
          </inertia>
        </inertial>
        <collision name='r9_R_roller_link_collision'>
          <pose>0 0 0 0 -0 0</pose>
          <geometry>
            <mesh>
              <scale>1 1 1</scale>
              <uri>model://rs_robot/meshes/STL/roller/roller.stl</uri>
            </mesh>
          </geometry>
          <surface>
            <contact>
              <ode>
                <max_vel>0.01</max_vel>
              </ode>
            </contact>
            <friction>
              <ode>
                <mu>1.5</mu>
                <mu2>1.5</mu2>
                <kp>1e15</kp>
                <kd>1e13</kd>
              </ode>
              <torsional>
                <ode/>
              </torsional>
            </friction>
            <bounce>
              <restitution_coefficient>0.01</restitution_coefficient>
              <threshold>0</threshold>
            </bounce>
          </surface>
          <max_contacts>10</max_contacts>
        </collision>
        <visual name='r9_R_roller_link_visual'>
          <pose>0 0 0 0 -0 0</pose>
          <geometry>
            <mesh>
              <scale>1 1 1</scale>
              <uri>model://rs_robot/meshes/DAE/roller/roller.dae</uri>
            </mesh>
          </geometry>
        </visual>
        <self_collide>0</self_collide>
        <enable_wind>0</enable_wind>
        <kinematic>0</kinematic>
      </link>
      <joint name='second_wheel_joint' type='revolute'>
        <pose relative_to='base_link'>0.086338 0.086338 -0.022 0 0 -0.785398</pose>
        <parent>base_link</parent>
        <child>second_wheel_link</child>
        <axis>
          <xyz>0 1 0</xyz>
          <limit>
            <effort>100</effort>
            <velocity>100</velocity>
            <lower>-1e+16</lower>
            <upper>1e+16</upper>
          </limit>
          <dynamics>
            <spring_reference>0</spring_reference>
            <spring_stiffness>0</spring_stiffness>
          </dynamics>
        </axis>
      </joint>
      <link name='second_wheel_link'>
        <pose relative_to='second_wheel_joint'>0 0 0 0 -0 0</pose>
        <inertial>
          <pose>0 -0.011 0 0 -0 0</pose>
          <mass>0.25</mass>
          <inertia>
            <ixx>0.00031</ixx>
            <ixy>0</ixy>
            <ixz>0</ixz>
            <iyy>0.0005</iyy>
            <iyz>0</iyz>
            <izz>0.00031</izz>
          </inertia>
        </inertial>
        <collision name='second_wheel_link_collision'>
          <pose>0 0 0 0 -0 0</pose>
          <geometry>
            <mesh>
              <scale>1 1 1</scale>
              <uri>model://rs_robot/meshes/STL/omni_wheel/omni_wheel.stl</uri>
            </mesh>
          </geometry>
          <surface>
            <contact>
              <ode>
                <max_vel>0.01</max_vel>
              </ode>
            </contact>
            <friction>
              <ode>
                <mu>1.5</mu>
                <mu2>1.5</mu2>
                <kp>1e15</kp>
                <kd>1e13</kd>
              </ode>
              <torsional>
                <ode/>
              </torsional>
            </friction>
            <bounce>
              <restitution_coefficient>0.01</restitution_coefficient>
              <threshold>0</threshold>
            </bounce>
          </surface>
          <max_contacts>10</max_contacts>
        </collision>
        <visual name='second_wheel_link_visual'>
          <pose>0 0 0 0 -0 0</pose>
          <geometry>
            <mesh>
              <scale>1 1 1</scale>
              <uri>model://rs_robot/meshes/DAE/omni_wheel/omni_wheel.dae</uri>
            </mesh>
          </geometry>
        </visual>
        <self_collide>0</self_collide>
        <enable_wind>0</enable_wind>
        <kinematic>0</kinematic>
      </link>
      <joint name='r10_S_roller_joint' type='revolute'>
        <pose relative_to='second_wheel_link'>-0.022885 0.006 -0.007436 1.25664 -0 1.5708</pose>
        <parent>second_wheel_link</parent>
        <child>r10_S_roller_link</child>
        <axis>
          <xyz>0 1 0</xyz>
          <limit>
            <lower>-1e+16</lower>
            <upper>1e+16</upper>
          </limit>
          <dynamics>
            <spring_reference>0</spring_reference>
            <spring_stiffness>0</spring_stiffness>
          </dynamics>
        </axis>
      </joint>
      <link name='r10_S_roller_link'>
        <pose relative_to='r10_S_roller_joint'>0 0 0 0 -0 0</pose>
        <inertial>
          <pose>0 0 0 0 -0 0</pose>
          <mass>0.009</mass>
          <inertia>
            <ixx>1.257e-06</ixx>
            <ixy>0</ixy>
            <ixz>0</ixz>
            <iyy>3.42e-07</iyy>
            <iyz>0</iyz>
            <izz>1.257e-06</izz>
          </inertia>
        </inertial>
        <collision name='r10_S_roller_link_collision'>
          <pose>0 0 0 0 -0 0</pose>
          <geometry>
            <mesh>
              <scale>1 1 1</scale>
              <uri>model://rs_robot/meshes/STL/roller/roller.stl</uri>
            </mesh>
          </geometry>
          <surface>
            <contact>
              <ode>
                <max_vel>0.01</max_vel>
              </ode>
            </contact>
            <friction>
              <ode>
                <mu>1.5</mu>
                <mu2>1.5</mu2>
                <kp>1e15</kp>
                <kd>1e13</kd>
              </ode>
              <torsional>
                <ode/>
              </torsional>
            </friction>
            <bounce>
              <restitution_coefficient>0.01</restitution_coefficient>
              <threshold>0</threshold>
            </bounce>
          </surface>
          <max_contacts>10</max_contacts>
        </collision>
        <visual name='r10_S_roller_link_visual'>
          <pose>0 0 0 0 -0 0</pose>
          <geometry>
            <mesh>
              <scale>1 1 1</scale>
              <uri>model://rs_robot/meshes/DAE/roller/roller.dae</uri>
            </mesh>
          </geometry>
        </visual>
        <self_collide>0</self_collide>
        <enable_wind>0</enable_wind>
        <kinematic>0</kinematic>
      </link>
      <joint name='r1_S_roller_joint' type='revolute'>
        <pose relative_to='second_wheel_link'>0 -0.006 0.024063 0 -0 1.5708</pose>
        <parent>second_wheel_link</parent>
        <child>r1_S_roller_link</child>
        <axis>
          <xyz>0 1 0</xyz>
          <limit>
            <lower>-1e+16</lower>
            <upper>1e+16</upper>
          </limit>
          <dynamics>
            <spring_reference>0</spring_reference>
            <spring_stiffness>0</spring_stiffness>
          </dynamics>
        </axis>
      </joint>
      <link name='r1_S_roller_link'>
        <pose relative_to='r1_S_roller_joint'>0 0 0 0 -0 0</pose>
        <inertial>
          <pose>0 0 0 0 -0 0</pose>
          <mass>0.009</mass>
          <inertia>
            <ixx>1.257e-06</ixx>
            <ixy>0</ixy>
            <ixz>0</ixz>
            <iyy>3.42e-07</iyy>
            <iyz>0</iyz>
            <izz>1.257e-06</izz>
          </inertia>
        </inertial>
        <collision name='r1_S_roller_link_collision'>
          <pose>0 0 0 0 -0 0</pose>
          <geometry>
            <mesh>
              <scale>1 1 1</scale>
              <uri>model://rs_robot/meshes/STL/roller/roller.stl</uri>
            </mesh>
          </geometry>
          <surface>
            <contact>
              <ode>
                <max_vel>0.01</max_vel>
              </ode>
            </contact>
            <friction>
              <ode>
                <mu>1.5</mu>
                <mu2>1.5</mu2>
                <kp>1e15</kp>
                <kd>1e13</kd>
              </ode>
              <torsional>
                <ode/>
              </torsional>
            </friction>
            <bounce>
              <restitution_coefficient>0.01</restitution_coefficient>
              <threshold>0</threshold>
            </bounce>
          </surface>
          <max_contacts>10</max_contacts>
        </collision>
        <visual name='r1_S_roller_link_visual'>
          <pose>0 0 0 0 -0 0</pose>
          <geometry>
            <mesh>
              <scale>1 1 1</scale>
              <uri>model://rs_robot/meshes/DAE/roller/roller.dae</uri>
            </mesh>
          </geometry>
        </visual>
        <self_collide>0</self_collide>
        <enable_wind>0</enable_wind>
        <kinematic>0</kinematic>
      </link>
      <joint name='r2_S_roller_joint' type='revolute'>
        <pose relative_to='second_wheel_link'>-0.022885 -0.006 0.007436 -1.25664 0 1.5708</pose>
        <parent>second_wheel_link</parent>
        <child>r2_S_roller_link</child>
        <axis>
          <xyz>0 1 0</xyz>
          <limit>
            <lower>-1e+16</lower>
            <upper>1e+16</upper>
          </limit>
          <dynamics>
            <spring_reference>0</spring_reference>
            <spring_stiffness>0</spring_stiffness>
          </dynamics>
        </axis>
      </joint>
      <link name='r2_S_roller_link'>
        <pose relative_to='r2_S_roller_joint'>0 0 0 0 -0 0</pose>
        <inertial>
          <pose>0 0 0 0 -0 0</pose>
          <mass>0.009</mass>
          <inertia>
            <ixx>1.257e-06</ixx>
            <ixy>0</ixy>
            <ixz>0</ixz>
            <iyy>3.42e-07</iyy>
            <iyz>0</iyz>
            <izz>1.257e-06</izz>
          </inertia>
        </inertial>
        <collision name='r2_S_roller_link_collision'>
          <pose>0 0 0 0 -0 0</pose>
          <geometry>
            <mesh>
              <scale>1 1 1</scale>
              <uri>model://rs_robot/meshes/STL/roller/roller.stl</uri>
            </mesh>
          </geometry>
          <surface>
            <contact>
              <ode>
                <max_vel>0.01</max_vel>
              </ode>
            </contact>
            <friction>
              <ode>
                <mu>1.5</mu>
                <mu2>1.5</mu2>
                <kp>1e15</kp>
                <kd>1e13</kd>
              </ode>
              <torsional>
                <ode/>
              </torsional>
            </friction>
            <bounce>
              <restitution_coefficient>0.01</restitution_coefficient>
              <threshold>0</threshold>
            </bounce>
          </surface>
          <max_contacts>10</max_contacts>
        </collision>
        <visual name='r2_S_roller_link_visual'>
          <pose>0 0 0 0 -0 0</pose>
          <geometry>
            <mesh>
              <scale>1 1 1</scale>
              <uri>model://rs_robot/meshes/DAE/roller/roller.dae</uri>
            </mesh>
          </geometry>
        </visual>
        <self_collide>0</self_collide>
        <enable_wind>0</enable_wind>
        <kinematic>0</kinematic>
      </link>
      <joint name='r3_S_roller_joint' type='revolute'>
        <pose relative_to='second_wheel_link'>-0.014144 -0.006 -0.019467 -2.51327 -0 1.5708</pose>
        <parent>second_wheel_link</parent>
        <child>r3_S_roller_link</child>
        <axis>
          <xyz>0 1 0</xyz>
          <limit>
            <lower>-1e+16</lower>
            <upper>1e+16</upper>
          </limit>
          <dynamics>
            <spring_reference>0</spring_reference>
            <spring_stiffness>0</spring_stiffness>
          </dynamics>
        </axis>
      </joint>
      <link name='r3_S_roller_link'>
        <pose relative_to='r3_S_roller_joint'>0 0 0 0 -0 0</pose>
        <inertial>
          <pose>0 0 0 0 -0 0</pose>
          <mass>0.009</mass>
          <inertia>
            <ixx>1.257e-06</ixx>
            <ixy>0</ixy>
            <ixz>0</ixz>
            <iyy>3.42e-07</iyy>
            <iyz>0</iyz>
            <izz>1.257e-06</izz>
          </inertia>
        </inertial>
        <collision name='r3_S_roller_link_collision'>
          <pose>0 0 0 0 -0 0</pose>
          <geometry>
            <mesh>
              <scale>1 1 1</scale>
              <uri>model://rs_robot/meshes/STL/roller/roller.stl</uri>
            </mesh>
          </geometry>
          <surface>
            <contact>
              <ode>
                <max_vel>0.01</max_vel>
              </ode>
            </contact>
            <friction>
              <ode>
                <mu>1.5</mu>
                <mu2>1.5</mu2>
                <kp>1e15</kp>
                <kd>1e13</kd>
              </ode>
              <torsional>
                <ode/>
              </torsional>
            </friction>
            <bounce>
              <restitution_coefficient>0.01</restitution_coefficient>
              <threshold>0</threshold>
            </bounce>
          </surface>
          <max_contacts>10</max_contacts>
        </collision>
        <visual name='r3_S_roller_link_visual'>
          <pose>0 0 0 0 -0 0</pose>
          <geometry>
            <mesh>
              <scale>1 1 1</scale>
              <uri>model://rs_robot/meshes/DAE/roller/roller.dae</uri>
            </mesh>
          </geometry>
        </visual>
        <self_collide>0</self_collide>
        <enable_wind>0</enable_wind>
        <kinematic>0</kinematic>
      </link>
      <joint name='r4_S_roller_joint' type='revolute'>
        <pose relative_to='second_wheel_link'>0.014144 -0.006 -0.019467 2.51327 -0 1.5708</pose>
        <parent>second_wheel_link</parent>
        <child>r4_S_roller_link</child>
        <axis>
          <xyz>0 1 0</xyz>
          <limit>
            <lower>-1e+16</lower>
            <upper>1e+16</upper>
          </limit>
          <dynamics>
            <spring_reference>0</spring_reference>
            <spring_stiffness>0</spring_stiffness>
          </dynamics>
        </axis>
      </joint>
      <link name='r4_S_roller_link'>
        <pose relative_to='r4_S_roller_joint'>0 0 0 0 -0 0</pose>
        <inertial>
          <pose>0 0 0 0 -0 0</pose>
          <mass>0.009</mass>
          <inertia>
            <ixx>1.257e-06</ixx>
            <ixy>0</ixy>
            <ixz>0</ixz>
            <iyy>3.42e-07</iyy>
            <iyz>0</iyz>
            <izz>1.257e-06</izz>
          </inertia>
        </inertial>
        <collision name='r4_S_roller_link_collision'>
          <pose>0 0 0 0 -0 0</pose>
          <geometry>
            <mesh>
              <scale>1 1 1</scale>
              <uri>model://rs_robot/meshes/STL/roller/roller.stl</uri>
            </mesh>
          </geometry>
          <surface>
            <contact>
              <ode>
                <max_vel>0.01</max_vel>
              </ode>
            </contact>
            <friction>
              <ode>
                <mu>1.5</mu>
                <mu2>1.5</mu2>
                <kp>1e15</kp>
                <kd>1e13</kd>
              </ode>
              <torsional>
                <ode/>
              </torsional>
            </friction>
            <bounce>
              <restitution_coefficient>0.01</restitution_coefficient>
              <threshold>0</threshold>
            </bounce>
          </surface>
          <max_contacts>10</max_contacts>
        </collision>
        <visual name='r4_S_roller_link_visual'>
          <pose>0 0 0 0 -0 0</pose>
          <geometry>
            <mesh>
              <scale>1 1 1</scale>
              <uri>model://rs_robot/meshes/DAE/roller/roller.dae</uri>
            </mesh>
          </geometry>
        </visual>
        <self_collide>0</self_collide>
        <enable_wind>0</enable_wind>
        <kinematic>0</kinematic>
      </link>
      <joint name='r5_S_roller_joint' type='revolute'>
        <pose relative_to='second_wheel_link'>0.022885 -0.006 0.007436 1.25664 -0 1.5708</pose>
        <parent>second_wheel_link</parent>
        <child>r5_S_roller_link</child>
        <axis>
          <xyz>0 1 0</xyz>
          <limit>
            <lower>-1e+16</lower>
            <upper>1e+16</upper>
          </limit>
          <dynamics>
            <spring_reference>0</spring_reference>
            <spring_stiffness>0</spring_stiffness>
          </dynamics>
        </axis>
      </joint>
      <link name='r5_S_roller_link'>
        <pose relative_to='r5_S_roller_joint'>0 0 0 0 -0 0</pose>
        <inertial>
          <pose>0 0 0 0 -0 0</pose>
          <mass>0.009</mass>
          <inertia>
            <ixx>1.257e-06</ixx>
            <ixy>0</ixy>
            <ixz>0</ixz>
            <iyy>3.42e-07</iyy>
            <iyz>0</iyz>
            <izz>1.257e-06</izz>
          </inertia>
        </inertial>
        <collision name='r5_S_roller_link_collision'>
          <pose>0 0 0 0 -0 0</pose>
          <geometry>
            <mesh>
              <scale>1 1 1</scale>
              <uri>model://rs_robot/meshes/STL/roller/roller.stl</uri>
            </mesh>
          </geometry>
          <surface>
            <contact>
              <ode>
                <max_vel>0.01</max_vel>
              </ode>
            </contact>
            <friction>
              <ode>
                <mu>1.5</mu>
                <mu2>1.5</mu2>
                <kp>1e15</kp>
                <kd>1e13</kd>
              </ode>
              <torsional>
                <ode/>
              </torsional>
            </friction>
            <bounce>
              <restitution_coefficient>0.01</restitution_coefficient>
              <threshold>0</threshold>
            </bounce>
          </surface>
          <max_contacts>10</max_contacts>
        </collision>
        <visual name='r5_S_roller_link_visual'>
          <pose>0 0 0 0 -0 0</pose>
          <geometry>
            <mesh>
              <scale>1 1 1</scale>
              <uri>model://rs_robot/meshes/DAE/roller/roller.dae</uri>
            </mesh>
          </geometry>
        </visual>
        <self_collide>0</self_collide>
        <enable_wind>0</enable_wind>
        <kinematic>0</kinematic>
      </link>
      <joint name='r6_S_roller_joint' type='revolute'>
        <pose relative_to='second_wheel_link'>0 0.006 -0.024063 0 -0 1.5708</pose>
        <parent>second_wheel_link</parent>
        <child>r6_S_roller_link</child>
        <axis>
          <xyz>0 1 0</xyz>
          <limit>
            <lower>-1e+16</lower>
            <upper>1e+16</upper>
          </limit>
          <dynamics>
            <spring_reference>0</spring_reference>
            <spring_stiffness>0</spring_stiffness>
          </dynamics>
        </axis>
      </joint>
      <link name='r6_S_roller_link'>
        <pose relative_to='r6_S_roller_joint'>0 0 0 0 -0 0</pose>
        <inertial>
          <pose>0 0 0 0 -0 0</pose>
          <mass>0.009</mass>
          <inertia>
            <ixx>1.257e-06</ixx>
            <ixy>0</ixy>
            <ixz>0</ixz>
            <iyy>3.42e-07</iyy>
            <iyz>0</iyz>
            <izz>1.257e-06</izz>
          </inertia>
        </inertial>
        <collision name='r6_S_roller_link_collision'>
          <pose>0 0 0 0 -0 0</pose>
          <geometry>
            <mesh>
              <scale>1 1 1</scale>
              <uri>model://rs_robot/meshes/STL/roller/roller.stl</uri>
            </mesh>
          </geometry>
          <surface>
            <contact>
              <ode>
                <max_vel>0.01</max_vel>
              </ode>
            </contact>
            <friction>
              <ode>
                <mu>1.5</mu>
                <mu2>1.5</mu2>
                <kp>1e15</kp>
                <kd>1e13</kd>
              </ode>
              <torsional>
                <ode/>
              </torsional>
            </friction>
            <bounce>
              <restitution_coefficient>0.01</restitution_coefficient>
              <threshold>0</threshold>
            </bounce>
          </surface>
          <max_contacts>10</max_contacts>
        </collision>
        <visual name='r6_S_roller_link_visual'>
          <pose>0 0 0 0 -0 0</pose>
          <geometry>
            <mesh>
              <scale>1 1 1</scale>
              <uri>model://rs_robot/meshes/DAE/roller/roller.dae</uri>
            </mesh>
          </geometry>
        </visual>
        <self_collide>0</self_collide>
        <enable_wind>0</enable_wind>
        <kinematic>0</kinematic>
      </link>
      <joint name='r7_S_roller_joint' type='revolute'>
        <pose relative_to='second_wheel_link'>0.022885 0.006 -0.007436 -1.25664 0 1.5708</pose>
        <parent>second_wheel_link</parent>
        <child>r7_S_roller_link</child>
        <axis>
          <xyz>0 1 0</xyz>
          <limit>
            <lower>-1e+16</lower>
            <upper>1e+16</upper>
          </limit>
          <dynamics>
            <spring_reference>0</spring_reference>
            <spring_stiffness>0</spring_stiffness>
          </dynamics>
        </axis>
      </joint>
      <link name='r7_S_roller_link'>
        <pose relative_to='r7_S_roller_joint'>0 0 0 0 -0 0</pose>
        <inertial>
          <pose>0 0 0 0 -0 0</pose>
          <mass>0.009</mass>
          <inertia>
            <ixx>1.257e-06</ixx>
            <ixy>0</ixy>
            <ixz>0</ixz>
            <iyy>3.42e-07</iyy>
            <iyz>0</iyz>
            <izz>1.257e-06</izz>
          </inertia>
        </inertial>
        <collision name='r7_S_roller_link_collision'>
          <pose>0 0 0 0 -0 0</pose>
          <geometry>
            <mesh>
              <scale>1 1 1</scale>
              <uri>model://rs_robot/meshes/STL/roller/roller.stl</uri>
            </mesh>
          </geometry>
          <surface>
            <contact>
              <ode>
                <max_vel>0.01</max_vel>
              </ode>
            </contact>
            <friction>
              <ode>
                <mu>1.5</mu>
                <mu2>1.5</mu2>
                <kp>1e15</kp>
                <kd>1e13</kd>
              </ode>
              <torsional>
                <ode/>
              </torsional>
            </friction>
            <bounce>
              <restitution_coefficient>0.01</restitution_coefficient>
              <threshold>0</threshold>
            </bounce>
          </surface>
          <max_contacts>10</max_contacts>
        </collision>
        <visual name='r7_S_roller_link_visual'>
          <pose>0 0 0 0 -0 0</pose>
          <geometry>
            <mesh>
              <scale>1 1 1</scale>
              <uri>model://rs_robot/meshes/DAE/roller/roller.dae</uri>
            </mesh>
          </geometry>
        </visual>
        <self_collide>0</self_collide>
        <enable_wind>0</enable_wind>
        <kinematic>0</kinematic>
      </link>
      <joint name='r8_S_roller_joint' type='revolute'>
        <pose relative_to='second_wheel_link'>0.014144 0.006 0.019467 -2.51327 -0 1.5708</pose>
        <parent>second_wheel_link</parent>
        <child>r8_S_roller_link</child>
        <axis>
          <xyz>0 1 0</xyz>
          <limit>
            <lower>-1e+16</lower>
            <upper>1e+16</upper>
          </limit>
          <dynamics>
            <spring_reference>0</spring_reference>
            <spring_stiffness>0</spring_stiffness>
          </dynamics>
        </axis>
      </joint>
      <link name='r8_S_roller_link'>
        <pose relative_to='r8_S_roller_joint'>0 0 0 0 -0 0</pose>
        <inertial>
          <pose>0 0 0 0 -0 0</pose>
          <mass>0.009</mass>
          <inertia>
            <ixx>1.257e-06</ixx>
            <ixy>0</ixy>
            <ixz>0</ixz>
            <iyy>3.42e-07</iyy>
            <iyz>0</iyz>
            <izz>1.257e-06</izz>
          </inertia>
        </inertial>
        <collision name='r8_S_roller_link_collision'>
          <pose>0 0 0 0 -0 0</pose>
          <geometry>
            <mesh>
              <scale>1 1 1</scale>
              <uri>model://rs_robot/meshes/STL/roller/roller.stl</uri>
            </mesh>
          </geometry>
          <surface>
            <contact>
              <ode>
                <max_vel>0.01</max_vel>
              </ode>
            </contact>
            <friction>
              <ode>
                <mu>1.5</mu>
                <mu2>1.5</mu2>
                <kp>1e15</kp>
                <kd>1e13</kd>
              </ode>
              <torsional>
                <ode/>
              </torsional>
            </friction>
            <bounce>
              <restitution_coefficient>0.01</restitution_coefficient>
              <threshold>0</threshold>
            </bounce>
          </surface>
          <max_contacts>10</max_contacts>
        </collision>
        <visual name='r8_S_roller_link_visual'>
          <pose>0 0 0 0 -0 0</pose>
          <geometry>
            <mesh>
              <scale>1 1 1</scale>
              <uri>model://rs_robot/meshes/DAE/roller/roller.dae</uri>
            </mesh>
          </geometry>
        </visual>
        <self_collide>0</self_collide>
        <enable_wind>0</enable_wind>
        <kinematic>0</kinematic>
      </link>
      <joint name='r9_S_roller_joint' type='revolute'>
        <pose relative_to='second_wheel_link'>-0.014144 0.006 0.019467 2.51327 -0 1.5708</pose>
        <parent>second_wheel_link</parent>
        <child>r9_S_roller_link</child>
        <axis>
          <xyz>0 1 0</xyz>
          <limit>
            <lower>-1e+16</lower>
            <upper>1e+16</upper>
          </limit>
          <dynamics>
            <spring_reference>0</spring_reference>
            <spring_stiffness>0</spring_stiffness>
          </dynamics>
        </axis>
      </joint>
      <link name='r9_S_roller_link'>
        <pose relative_to='r9_S_roller_joint'>0 0 0 0 -0 0</pose>
        <inertial>
          <pose>0 0 0 0 -0 0</pose>
          <mass>0.009</mass>
          <inertia>
            <ixx>1.257e-06</ixx>
            <ixy>0</ixy>
            <ixz>0</ixz>
            <iyy>3.42e-07</iyy>
            <iyz>0</iyz>
            <izz>1.257e-06</izz>
          </inertia>
        </inertial>
        <collision name='r9_S_roller_link_collision'>
          <pose>0 0 0 0 -0 0</pose>
          <geometry>
            <mesh>
              <scale>1 1 1</scale>
              <uri>model://rs_robot/meshes/STL/roller/roller.stl</uri>
            </mesh>
          </geometry>
          <surface>
            <contact>
              <ode>
                <max_vel>0.01</max_vel>
              </ode>
            </contact>
            <friction>
              <ode>
                <mu>1.5</mu>
                <mu2>1.5</mu2>
                <kp>1e15</kp>
                <kd>1e13</kd>
              </ode>
              <torsional>
                <ode/>
              </torsional>
            </friction>
            <bounce>
              <restitution_coefficient>0.01</restitution_coefficient>
              <threshold>0</threshold>
            </bounce>
          </surface>
          <max_contacts>10</max_contacts>
        </collision>
        <visual name='r9_S_roller_link_visual'>
          <pose>0 0 0 0 -0 0</pose>
          <geometry>
            <mesh>
              <scale>1 1 1</scale>
              <uri>model://rs_robot/meshes/DAE/roller/roller.dae</uri>
            </mesh>
          </geometry>
        </visual>
        <self_collide>0</self_collide>
        <enable_wind>0</enable_wind>
        <kinematic>0</kinematic>
      </link>
      <joint name='third_wheel_joint' type='revolute'>
        <pose relative_to='base_link'>-0.086338 0.086338 -0.022 0 -0 0.785398</pose>
        <parent>base_link</parent>
        <child>third_wheel_link</child>
        <axis>
          <xyz>0 1 0</xyz>
          <limit>
            <effort>100</effort>
            <velocity>100</velocity>
            <lower>-1e+16</lower>
            <upper>1e+16</upper>
          </limit>
          <dynamics>
            <spring_reference>0</spring_reference>
            <spring_stiffness>0</spring_stiffness>
          </dynamics>
        </axis>
      </joint>
      <link name='third_wheel_link'>
        <pose relative_to='third_wheel_joint'>0 0 0 0 -0 0</pose>
        <inertial>
          <pose>0 -0.011 0 0 -0 0</pose>
          <mass>0.25</mass>
          <inertia>
            <ixx>0.00031</ixx>
            <ixy>0</ixy>
            <ixz>0</ixz>
            <iyy>0.0005</iyy>
            <iyz>0</iyz>
            <izz>0.00031</izz>
          </inertia>
        </inertial>
        <collision name='third_wheel_link_collision'>
          <pose>0 0 0 0 -0 0</pose>
          <geometry>
            <mesh>
              <scale>1 1 1</scale>
              <uri>model://rs_robot/meshes/STL/omni_wheel/omni_wheel.stl</uri>
            </mesh>
          </geometry>
          <surface>
            <contact>
              <ode>
                <max_vel>0.01</max_vel>
              </ode>
            </contact>
            <friction>
              <ode>
                <mu>1.5</mu>
                <mu2>1.5</mu2>
                <kp>1e15</kp>
                <kd>1e13</kd>
              </ode>
              <torsional>
                <ode/>
              </torsional>
            </friction>
            <bounce>
              <restitution_coefficient>0.01</restitution_coefficient>
              <threshold>0</threshold>
            </bounce>
          </surface>
          <max_contacts>10</max_contacts>
        </collision>
        <visual name='third_wheel_link_visual'>
          <pose>0 0 0 0 -0 0</pose>
          <geometry>
            <mesh>
              <scale>1 1 1</scale>
              <uri>model://rs_robot/meshes/DAE/omni_wheel/omni_wheel.dae</uri>
            </mesh>
          </geometry>
        </visual>
        <self_collide>0</self_collide>
        <enable_wind>0</enable_wind>
        <kinematic>0</kinematic>
      </link>
      <joint name='r10_T_roller_joint' type='revolute'>
        <pose relative_to='third_wheel_link'>-0.022885 0.006 -0.007436 1.25664 -0 1.5708</pose>
        <parent>third_wheel_link</parent>
        <child>r10_T_roller_link</child>
        <axis>
          <xyz>0 1 0</xyz>
          <limit>
            <lower>-1e+16</lower>
            <upper>1e+16</upper>
          </limit>
          <dynamics>
            <spring_reference>0</spring_reference>
            <spring_stiffness>0</spring_stiffness>
          </dynamics>
        </axis>
      </joint>
      <link name='r10_T_roller_link'>
        <pose relative_to='r10_T_roller_joint'>0 0 0 0 -0 0</pose>
        <inertial>
          <pose>0 0 0 0 -0 0</pose>
          <mass>0.009</mass>
          <inertia>
            <ixx>1.257e-06</ixx>
            <ixy>0</ixy>
            <ixz>0</ixz>
            <iyy>3.42e-07</iyy>
            <iyz>0</iyz>
            <izz>1.257e-06</izz>
          </inertia>
        </inertial>
        <collision name='r10_T_roller_link_collision'>
          <pose>0 0 0 0 -0 0</pose>
          <geometry>
            <mesh>
              <scale>1 1 1</scale>
              <uri>model://rs_robot/meshes/STL/roller/roller.stl</uri>
            </mesh>
          </geometry>
          <surface>
            <contact>
              <ode>
                <max_vel>0.01</max_vel>
              </ode>
            </contact>
            <friction>
              <ode>
                <mu>1.5</mu>
                <mu2>1.5</mu2>
                <kp>1e15</kp>
                <kd>1e13</kd>
              </ode>
              <torsional>
                <ode/>
              </torsional>
            </friction>
            <bounce>
              <restitution_coefficient>0.01</restitution_coefficient>
              <threshold>0</threshold>
            </bounce>
          </surface>
          <max_contacts>10</max_contacts>
        </collision>
        <visual name='r10_T_roller_link_visual'>
          <pose>0 0 0 0 -0 0</pose>
          <geometry>
            <mesh>
              <scale>1 1 1</scale>
              <uri>model://rs_robot/meshes/DAE/roller/roller.dae</uri>
            </mesh>
          </geometry>
        </visual>
        <self_collide>0</self_collide>
        <enable_wind>0</enable_wind>
        <kinematic>0</kinematic>
      </link>
      <joint name='r1_T_roller_joint' type='revolute'>
        <pose relative_to='third_wheel_link'>0 -0.006 0.024063 0 -0 1.5708</pose>
        <parent>third_wheel_link</parent>
        <child>r1_T_roller_link</child>
        <axis>
          <xyz>0 1 0</xyz>
          <limit>
            <lower>-1e+16</lower>
            <upper>1e+16</upper>
          </limit>
          <dynamics>
            <spring_reference>0</spring_reference>
            <spring_stiffness>0</spring_stiffness>
          </dynamics>
        </axis>
      </joint>
      <link name='r1_T_roller_link'>
        <pose relative_to='r1_T_roller_joint'>0 0 0 0 -0 0</pose>
        <inertial>
          <pose>0 0 0 0 -0 0</pose>
          <mass>0.009</mass>
          <inertia>
            <ixx>1.257e-06</ixx>
            <ixy>0</ixy>
            <ixz>0</ixz>
            <iyy>3.42e-07</iyy>
            <iyz>0</iyz>
            <izz>1.257e-06</izz>
          </inertia>
        </inertial>
        <collision name='r1_T_roller_link_collision'>
          <pose>0 0 0 0 -0 0</pose>
          <geometry>
            <mesh>
              <scale>1 1 1</scale>
              <uri>model://rs_robot/meshes/STL/roller/roller.stl</uri>
            </mesh>
          </geometry>
          <surface>
            <contact>
              <ode>
                <max_vel>0.01</max_vel>
              </ode>
            </contact>
            <friction>
              <ode>
                <mu>1.5</mu>
                <mu2>1.5</mu2>
                <kp>1e15</kp>
                <kd>1e13</kd>
              </ode>
              <torsional>
                <ode/>
              </torsional>
            </friction>
            <bounce>
              <restitution_coefficient>0.01</restitution_coefficient>
              <threshold>0</threshold>
            </bounce>
          </surface>
          <max_contacts>10</max_contacts>
        </collision>
        <visual name='r1_T_roller_link_visual'>
          <pose>0 0 0 0 -0 0</pose>
          <geometry>
            <mesh>
              <scale>1 1 1</scale>
              <uri>model://rs_robot/meshes/DAE/roller/roller.dae</uri>
            </mesh>
          </geometry>
        </visual>
        <self_collide>0</self_collide>
        <enable_wind>0</enable_wind>
        <kinematic>0</kinematic>
      </link>
      <joint name='r2_T_roller_joint' type='revolute'>
        <pose relative_to='third_wheel_link'>-0.022885 -0.006 0.007436 -1.25664 0 1.5708</pose>
        <parent>third_wheel_link</parent>
        <child>r2_T_roller_link</child>
        <axis>
          <xyz>0 1 0</xyz>
          <limit>
            <lower>-1e+16</lower>
            <upper>1e+16</upper>
          </limit>
          <dynamics>
            <spring_reference>0</spring_reference>
            <spring_stiffness>0</spring_stiffness>
          </dynamics>
        </axis>
      </joint>
      <link name='r2_T_roller_link'>
        <pose relative_to='r2_T_roller_joint'>0 0 0 0 -0 0</pose>
        <inertial>
          <pose>0 0 0 0 -0 0</pose>
          <mass>0.009</mass>
          <inertia>
            <ixx>1.257e-06</ixx>
            <ixy>0</ixy>
            <ixz>0</ixz>
            <iyy>3.42e-07</iyy>
            <iyz>0</iyz>
            <izz>1.257e-06</izz>
          </inertia>
        </inertial>
        <collision name='r2_T_roller_link_collision'>
          <pose>0 0 0 0 -0 0</pose>
          <geometry>
            <mesh>
              <scale>1 1 1</scale>
              <uri>model://rs_robot/meshes/STL/roller/roller.stl</uri>
            </mesh>
          </geometry>
          <surface>
            <contact>
              <ode>
                <max_vel>0.01</max_vel>
              </ode>
            </contact>
            <friction>
              <ode>
                <mu>1.5</mu>
                <mu2>1.5</mu2>
                <kp>1e15</kp>
                <kd>1e13</kd>
              </ode>
              <torsional>
                <ode/>
              </torsional>
            </friction>
            <bounce>
              <restitution_coefficient>0.01</restitution_coefficient>
              <threshold>0</threshold>
            </bounce>
          </surface>
          <max_contacts>10</max_contacts>
        </collision>
        <visual name='r2_T_roller_link_visual'>
          <pose>0 0 0 0 -0 0</pose>
          <geometry>
            <mesh>
              <scale>1 1 1</scale>
              <uri>model://rs_robot/meshes/DAE/roller/roller.dae</uri>
            </mesh>
          </geometry>
        </visual>
        <self_collide>0</self_collide>
        <enable_wind>0</enable_wind>
        <kinematic>0</kinematic>
      </link>
      <joint name='r3_T_roller_joint' type='revolute'>
        <pose relative_to='third_wheel_link'>-0.014144 -0.006 -0.019467 -2.51327 -0 1.5708</pose>
        <parent>third_wheel_link</parent>
        <child>r3_T_roller_link</child>
        <axis>
          <xyz>0 1 0</xyz>
          <limit>
            <lower>-1e+16</lower>
            <upper>1e+16</upper>
          </limit>
          <dynamics>
            <spring_reference>0</spring_reference>
            <spring_stiffness>0</spring_stiffness>
          </dynamics>
        </axis>
      </joint>
      <link name='r3_T_roller_link'>
        <pose relative_to='r3_T_roller_joint'>0 0 0 0 -0 0</pose>
        <inertial>
          <pose>0 0 0 0 -0 0</pose>
          <mass>0.009</mass>
          <inertia>
            <ixx>1.257e-06</ixx>
            <ixy>0</ixy>
            <ixz>0</ixz>
            <iyy>3.42e-07</iyy>
            <iyz>0</iyz>
            <izz>1.257e-06</izz>
          </inertia>
        </inertial>
        <collision name='r3_T_roller_link_collision'>
          <pose>0 0 0 0 -0 0</pose>
          <geometry>
            <mesh>
              <scale>1 1 1</scale>
              <uri>model://rs_robot/meshes/STL/roller/roller.stl</uri>
            </mesh>
          </geometry>
          <surface>
            <contact>
              <ode>
                <max_vel>0.01</max_vel>
              </ode>
            </contact>
            <friction>
              <ode>
                <mu>1.5</mu>
                <mu2>1.5</mu2>
                <kp>1e15</kp>
                <kd>1e13</kd>
              </ode>
              <torsional>
                <ode/>
              </torsional>
            </friction>
            <bounce>
              <restitution_coefficient>0.01</restitution_coefficient>
              <threshold>0</threshold>
            </bounce>
          </surface>
          <max_contacts>10</max_contacts>
        </collision>
        <visual name='r3_T_roller_link_visual'>
          <pose>0 0 0 0 -0 0</pose>
          <geometry>
            <mesh>
              <scale>1 1 1</scale>
              <uri>model://rs_robot/meshes/DAE/roller/roller.dae</uri>
            </mesh>
          </geometry>
        </visual>
        <self_collide>0</self_collide>
        <enable_wind>0</enable_wind>
        <kinematic>0</kinematic>
      </link>
      <joint name='r4_T_roller_joint' type='revolute'>
        <pose relative_to='third_wheel_link'>0.014144 -0.006 -0.019467 2.51327 -0 1.5708</pose>
        <parent>third_wheel_link</parent>
        <child>r4_T_roller_link</child>
        <axis>
          <xyz>0 1 0</xyz>
          <limit>
            <lower>-1e+16</lower>
            <upper>1e+16</upper>
          </limit>
          <dynamics>
            <spring_reference>0</spring_reference>
            <spring_stiffness>0</spring_stiffness>
          </dynamics>
        </axis>
      </joint>
      <link name='r4_T_roller_link'>
        <pose relative_to='r4_T_roller_joint'>0 0 0 0 -0 0</pose>
        <inertial>
          <pose>0 0 0 0 -0 0</pose>
          <mass>0.009</mass>
          <inertia>
            <ixx>1.257e-06</ixx>
            <ixy>0</ixy>
            <ixz>0</ixz>
            <iyy>3.42e-07</iyy>
            <iyz>0</iyz>
            <izz>1.257e-06</izz>
          </inertia>
        </inertial>
        <collision name='r4_T_roller_link_collision'>
          <pose>0 0 0 0 -0 0</pose>
          <geometry>
            <mesh>
              <scale>1 1 1</scale>
              <uri>model://rs_robot/meshes/STL/roller/roller.stl</uri>
            </mesh>
          </geometry>
          <surface>
            <contact>
              <ode>
                <max_vel>0.01</max_vel>
              </ode>
            </contact>
            <friction>
              <ode>
                <mu>1.5</mu>
                <mu2>1.5</mu2>
                <kp>1e15</kp>
                <kd>1e13</kd>
              </ode>
              <torsional>
                <ode/>
              </torsional>
            </friction>
            <bounce>
              <restitution_coefficient>0.01</restitution_coefficient>
              <threshold>0</threshold>
            </bounce>
          </surface>
          <max_contacts>10</max_contacts>
        </collision>
        <visual name='r4_T_roller_link_visual'>
          <pose>0 0 0 0 -0 0</pose>
          <geometry>
            <mesh>
              <scale>1 1 1</scale>
              <uri>model://rs_robot/meshes/DAE/roller/roller.dae</uri>
            </mesh>
          </geometry>
        </visual>
        <self_collide>0</self_collide>
        <enable_wind>0</enable_wind>
        <kinematic>0</kinematic>
      </link>
      <joint name='r5_T_roller_joint' type='revolute'>
        <pose relative_to='third_wheel_link'>0.022885 -0.006 0.007436 1.25664 -0 1.5708</pose>
        <parent>third_wheel_link</parent>
        <child>r5_T_roller_link</child>
        <axis>
          <xyz>0 1 0</xyz>
          <limit>
            <lower>-1e+16</lower>
            <upper>1e+16</upper>
          </limit>
          <dynamics>
            <spring_reference>0</spring_reference>
            <spring_stiffness>0</spring_stiffness>
          </dynamics>
        </axis>
      </joint>
      <link name='r5_T_roller_link'>
        <pose relative_to='r5_T_roller_joint'>0 0 0 0 -0 0</pose>
        <inertial>
          <pose>0 0 0 0 -0 0</pose>
          <mass>0.009</mass>
          <inertia>
            <ixx>1.257e-06</ixx>
            <ixy>0</ixy>
            <ixz>0</ixz>
            <iyy>3.42e-07</iyy>
            <iyz>0</iyz>
            <izz>1.257e-06</izz>
          </inertia>
        </inertial>
        <collision name='r5_T_roller_link_collision'>
          <pose>0 0 0 0 -0 0</pose>
          <geometry>
            <mesh>
              <scale>1 1 1</scale>
              <uri>model://rs_robot/meshes/STL/roller/roller.stl</uri>
            </mesh>
          </geometry>
          <surface>
            <contact>
              <ode>
                <max_vel>0.01</max_vel>
              </ode>
            </contact>
            <friction>
              <ode>
                <mu>1.5</mu>
                <mu2>1.5</mu2>
                <kp>1e15</kp>
                <kd>1e13</kd>
              </ode>
              <torsional>
                <ode/>
              </torsional>
            </friction>
            <bounce>
              <restitution_coefficient>0.01</restitution_coefficient>
              <threshold>0</threshold>
            </bounce>
          </surface>
          <max_contacts>10</max_contacts>
        </collision>
        <visual name='r5_T_roller_link_visual'>
          <pose>0 0 0 0 -0 0</pose>
          <geometry>
            <mesh>
              <scale>1 1 1</scale>
              <uri>model://rs_robot/meshes/DAE/roller/roller.dae</uri>
            </mesh>
          </geometry>
        </visual>
        <self_collide>0</self_collide>
        <enable_wind>0</enable_wind>
        <kinematic>0</kinematic>
      </link>
      <joint name='r6_T_roller_joint' type='revolute'>
        <pose relative_to='third_wheel_link'>0 0.006 -0.024063 0 -0 1.5708</pose>
        <parent>third_wheel_link</parent>
        <child>r6_T_roller_link</child>
        <axis>
          <xyz>0 1 0</xyz>
          <limit>
            <lower>-1e+16</lower>
            <upper>1e+16</upper>
          </limit>
          <dynamics>
            <spring_reference>0</spring_reference>
            <spring_stiffness>0</spring_stiffness>
          </dynamics>
        </axis>
      </joint>
      <link name='r6_T_roller_link'>
        <pose relative_to='r6_T_roller_joint'>0 0 0 0 -0 0</pose>
        <inertial>
          <pose>0 0 0 0 -0 0</pose>
          <mass>0.009</mass>
          <inertia>
            <ixx>1.257e-06</ixx>
            <ixy>0</ixy>
            <ixz>0</ixz>
            <iyy>3.42e-07</iyy>
            <iyz>0</iyz>
            <izz>1.257e-06</izz>
          </inertia>
        </inertial>
        <collision name='r6_T_roller_link_collision'>
          <pose>0 0 0 0 -0 0</pose>
          <geometry>
            <mesh>
              <scale>1 1 1</scale>
              <uri>model://rs_robot/meshes/STL/roller/roller.stl</uri>
            </mesh>
          </geometry>
          <surface>
            <contact>
              <ode>
                <max_vel>0.01</max_vel>
              </ode>
            </contact>
            <friction>
              <ode>
                <mu>1.5</mu>
                <mu2>1.5</mu2>
                <kp>1e15</kp>
                <kd>1e13</kd>
              </ode>
              <torsional>
                <ode/>
              </torsional>
            </friction>
            <bounce>
              <restitution_coefficient>0.01</restitution_coefficient>
              <threshold>0</threshold>
            </bounce>
          </surface>
          <max_contacts>10</max_contacts>
        </collision>
        <visual name='r6_T_roller_link_visual'>
          <pose>0 0 0 0 -0 0</pose>
          <geometry>
            <mesh>
              <scale>1 1 1</scale>
              <uri>model://rs_robot/meshes/DAE/roller/roller.dae</uri>
            </mesh>
          </geometry>
        </visual>
        <self_collide>0</self_collide>
        <enable_wind>0</enable_wind>
        <kinematic>0</kinematic>
      </link>
      <joint name='r7_T_roller_joint' type='revolute'>
        <pose relative_to='third_wheel_link'>0.022885 0.006 -0.007436 -1.25664 0 1.5708</pose>
        <parent>third_wheel_link</parent>
        <child>r7_T_roller_link</child>
        <axis>
          <xyz>0 1 0</xyz>
          <limit>
            <lower>-1e+16</lower>
            <upper>1e+16</upper>
          </limit>
          <dynamics>
            <spring_reference>0</spring_reference>
            <spring_stiffness>0</spring_stiffness>
          </dynamics>
        </axis>
      </joint>
      <link name='r7_T_roller_link'>
        <pose relative_to='r7_T_roller_joint'>0 0 0 0 -0 0</pose>
        <inertial>
          <pose>0 0 0 0 -0 0</pose>
          <mass>0.009</mass>
          <inertia>
            <ixx>1.257e-06</ixx>
            <ixy>0</ixy>
            <ixz>0</ixz>
            <iyy>3.42e-07</iyy>
            <iyz>0</iyz>
            <izz>1.257e-06</izz>
          </inertia>
        </inertial>
        <collision name='r7_T_roller_link_collision'>
          <pose>0 0 0 0 -0 0</pose>
          <geometry>
            <mesh>
              <scale>1 1 1</scale>
              <uri>model://rs_robot/meshes/STL/roller/roller.stl</uri>
            </mesh>
          </geometry>
          <surface>
            <contact>
              <ode>
                <max_vel>0.01</max_vel>
              </ode>
            </contact>
            <friction>
              <ode>
                <mu>1.5</mu>
                <mu2>1.5</mu2>
                <kp>1e15</kp>
                <kd>1e13</kd>
              </ode>
              <torsional>
                <ode/>
              </torsional>
            </friction>
            <bounce>
              <restitution_coefficient>0.01</restitution_coefficient>
              <threshold>0</threshold>
            </bounce>
          </surface>
          <max_contacts>10</max_contacts>
        </collision>
        <visual name='r7_T_roller_link_visual'>
          <pose>0 0 0 0 -0 0</pose>
          <geometry>
            <mesh>
              <scale>1 1 1</scale>
              <uri>model://rs_robot/meshes/DAE/roller/roller.dae</uri>
            </mesh>
          </geometry>
        </visual>
        <self_collide>0</self_collide>
        <enable_wind>0</enable_wind>
        <kinematic>0</kinematic>
      </link>
      <joint name='r8_T_roller_joint' type='revolute'>
        <pose relative_to='third_wheel_link'>0.014144 0.006 0.019467 -2.51327 -0 1.5708</pose>
        <parent>third_wheel_link</parent>
        <child>r8_T_roller_link</child>
        <axis>
          <xyz>0 1 0</xyz>
          <limit>
            <lower>-1e+16</lower>
            <upper>1e+16</upper>
          </limit>
          <dynamics>
            <spring_reference>0</spring_reference>
            <spring_stiffness>0</spring_stiffness>
          </dynamics>
        </axis>
      </joint>
      <link name='r8_T_roller_link'>
        <pose relative_to='r8_T_roller_joint'>0 0 0 0 -0 0</pose>
        <inertial>
          <pose>0 0 0 0 -0 0</pose>
          <mass>0.009</mass>
          <inertia>
            <ixx>1.257e-06</ixx>
            <ixy>0</ixy>
            <ixz>0</ixz>
            <iyy>3.42e-07</iyy>
            <iyz>0</iyz>
            <izz>1.257e-06</izz>
          </inertia>
        </inertial>
        <collision name='r8_T_roller_link_collision'>
          <pose>0 0 0 0 -0 0</pose>
          <geometry>
            <mesh>
              <scale>1 1 1</scale>
              <uri>model://rs_robot/meshes/STL/roller/roller.stl</uri>
            </mesh>
          </geometry>
          <surface>
            <contact>
              <ode>
                <max_vel>0.01</max_vel>
              </ode>
            </contact>
            <friction>
              <ode>
                <mu>1.5</mu>
                <mu2>1.5</mu2>
                <kp>1e15</kp>
                <kd>1e13</kd>
              </ode>
              <torsional>
                <ode/>
              </torsional>
            </friction>
            <bounce>
              <restitution_coefficient>0.01</restitution_coefficient>
              <threshold>0</threshold>
            </bounce>
          </surface>
          <max_contacts>10</max_contacts>
        </collision>
        <visual name='r8_T_roller_link_visual'>
          <pose>0 0 0 0 -0 0</pose>
          <geometry>
            <mesh>
              <scale>1 1 1</scale>
              <uri>model://rs_robot/meshes/DAE/roller/roller.dae</uri>
            </mesh>
          </geometry>
        </visual>
        <self_collide>0</self_collide>
        <enable_wind>0</enable_wind>
        <kinematic>0</kinematic>
      </link>
      <joint name='r9_T_roller_joint' type='revolute'>
        <pose relative_to='third_wheel_link'>-0.014144 0.006 0.019467 2.51327 -0 1.5708</pose>
        <parent>third_wheel_link</parent>
        <child>r9_T_roller_link</child>
        <axis>
          <xyz>0 1 0</xyz>
          <limit>
            <lower>-1e+16</lower>
            <upper>1e+16</upper>
          </limit>
          <dynamics>
            <spring_reference>0</spring_reference>
            <spring_stiffness>0</spring_stiffness>
          </dynamics>
        </axis>
      </joint>
      <link name='r9_T_roller_link'>
        <pose relative_to='r9_T_roller_joint'>0 0 0 0 -0 0</pose>
        <inertial>
          <pose>0 0 0 0 -0 0</pose>
          <mass>0.009</mass>
          <inertia>
            <ixx>1.257e-06</ixx>
            <ixy>0</ixy>
            <ixz>0</ixz>
            <iyy>3.42e-07</iyy>
            <iyz>0</iyz>
            <izz>1.257e-06</izz>
          </inertia>
        </inertial>
        <collision name='r9_T_roller_link_collision'>
          <pose>0 0 0 0 -0 0</pose>
          <geometry>
            <mesh>
              <scale>1 1 1</scale>
              <uri>model://rs_robot/meshes/STL/roller/roller.stl</uri>
            </mesh>
          </geometry>
          <surface>
            <contact>
              <ode>
                <max_vel>0.01</max_vel>
              </ode>
            </contact>
            <friction>
              <ode>
                <mu>1.5</mu>
                <mu2>1.5</mu2>
                <kp>1e15</kp>
                <kd>1e13</kd>
              </ode>
              <torsional>
                <ode/>
              </torsional>
            </friction>
            <bounce>
              <restitution_coefficient>0.01</restitution_coefficient>
              <threshold>0</threshold>
            </bounce>
          </surface>
          <max_contacts>10</max_contacts>
        </collision>
        <visual name='r9_T_roller_link_visual'>
          <pose>0 0 0 0 -0 0</pose>
          <geometry>
            <mesh>
              <scale>1 1 1</scale>
              <uri>model://rs_robot/meshes/DAE/roller/roller.dae</uri>
            </mesh>
          </geometry>
        </visual>
        <self_collide>0</self_collide>
        <enable_wind>0</enable_wind>
        <kinematic>0</kinematic>
      </link>
      <static>0</static>
      <plugin name='omni_robot_joint_state' filename='libgazebo_ros_joint_state_publisher.so'>
        <ros>
          <remapping>~/out:=joint_states</remapping>
        </ros>
        <update_rate>20</update_rate>
        <joint_name>first_wheel_joint</joint_name>
        <joint_name>second_wheel_joint</joint_name>
        <joint_name>third_wheel_joint</joint_name>
        <joint_name>fourth_wheel_joint</joint_name>
        <joint_name>r1_F_roller_joint</joint_name>
        <joint_name>r2_F_roller_joint</joint_name>
        <joint_name>r3_F_roller_joint</joint_name>
        <joint_name>r4_F_roller_joint</joint_name>
        <joint_name>r5_F_roller_joint</joint_name>
        <joint_name>r6_F_roller_joint</joint_name>
        <joint_name>r7_F_roller_joint</joint_name>
        <joint_name>r8_F_roller_joint</joint_name>
        <joint_name>r9_F_roller_joint</joint_name>
        <joint_name>r10_F_roller_joint</joint_name>
        <joint_name>r1_R_roller_joint</joint_name>
        <joint_name>r2_R_roller_joint</joint_name>
        <joint_name>r3_R_roller_joint</joint_name>
        <joint_name>r4_R_roller_joint</joint_name>
        <joint_name>r5_R_roller_joint</joint_name>
        <joint_name>r6_R_roller_joint</joint_name>
        <joint_name>r7_R_roller_joint</joint_name>
        <joint_name>r8_R_roller_joint</joint_name>
        <joint_name>r9_R_roller_joint</joint_name>
        <joint_name>r10_R_roller_joint</joint_name>
        <joint_name>r1_S_roller_joint</joint_name>
        <joint_name>r2_S_roller_joint</joint_name>
        <joint_name>r3_S_roller_joint</joint_name>
        <joint_name>r4_S_roller_joint</joint_name>
        <joint_name>r5_S_roller_joint</joint_name>
        <joint_name>r6_S_roller_joint</joint_name>
        <joint_name>r7_S_roller_joint</joint_name>
        <joint_name>r8_S_roller_joint</joint_name>
        <joint_name>r9_S_roller_joint</joint_name>
        <joint_name>r10_S_roller_joint</joint_name>
        <joint_name>r1_T_roller_joint</joint_name>
        <joint_name>r2_T_roller_joint</joint_name>
        <joint_name>r3_T_roller_joint</joint_name>
        <joint_name>r4_T_roller_joint</joint_name>
        <joint_name>r5_T_roller_joint</joint_name>
        <joint_name>r6_T_roller_joint</joint_name>
        <joint_name>r7_T_roller_joint</joint_name>
        <joint_name>r8_T_roller_joint</joint_name>
        <joint_name>r9_T_roller_joint</joint_name>
        <joint_name>r10_T_roller_joint</joint_name>
      </plugin>
      <plugin name='gazebo_ros2_control' filename='libgazebo_ros2_control.so'>
        <parameters>/home/logan/4wd_ws/install/gazebo_simulation/share/gazebo_simulation/models/rs_robot/config/controllers.yaml</parameters>
      </plugin>
      <pose>0 0 0.1 0 -0 0</pose>
      <ros2_control name='GazeboSystem' type='system'>
        <hardware>
          <plugin>gazebo_ros2_control/GazeboSystem</plugin>
        </hardware>
        <joint name='first_wheel_joint'>
          <command_interface name='velocity'>
            <param name='min'>-3.14</param>
            <param name='max'>3.14</param>
          </command_interface>
          <state_interface name='velocity'/>
        </joint>
        <joint name='second_wheel_joint'>
          <command_interface name='velocity'>
            <param name='min'>-3.14</param>
            <param name='max'>3.14</param>
          </command_interface>
          <state_interface name='velocity'/>
        </joint>
        <joint name='third_wheel_joint'>
          <command_interface name='velocity'>
            <param name='min'>-3.14</param>
            <param name='max'>3.14</param>
          </command_interface>
          <state_interface name='velocity'/>
        </joint>
        <joint name='fourth_wheel_joint'>
          <command_interface name='velocity'>
            <param name='min'>-3.14</param>
            <param name='max'>3.14</param>
          </command_interface>
          <state_interface name='velocity'/>
        </joint>
      </ros2_control>
    </model>
    <model name='omni_stage'>
      <static>1</static>
      <link name='link'>
        <collision name='collision'>
          <geometry>
            <mesh>
              <scale>1 1 1</scale>
              <uri>model://omni_stage/meshes/omni_stage.stl</uri>
            </mesh>
            <surface>
              <friction>
                <ode>
                  <mu>1.2</mu>
                  <mu2>1.2</mu2>
                </ode>
              </friction>
            </surface>
          </geometry>
          <max_contacts>10</max_contacts>
          <surface>
            <contact>
              <ode/>
            </contact>
            <bounce/>
            <friction>
              <torsional>
                <ode/>
              </torsional>
              <ode/>
            </friction>
          </surface>
        </collision>
        <visual name='visual'>
          <geometry>
            <mesh>
              <scale>1 1 1</scale>
              <uri>model://omni_stage/meshes/omni_stage.dae</uri>
            </mesh>
          </geometry>
        </visual>
        <self_collide>0</self_collide>
        <enable_wind>0</enable_wind>
        <kinematic>0</kinematic>
      </link>
      <pose>0 0 0 0 -0 0</pose>
    </model>
    <gravity>0 0 -9.8</gravity>
    <magnetic_field>6e-06 2.3e-05 -4.2e-05</magnetic_field>
    <atmosphere type='adiabatic'/>
    <physics type='ode'>
      <max_step_size>0.001</max_step_size>
      <real_time_factor>1</real_time_factor>
      <real_time_update_rate>1000</real_time_update_rate>
    </physics>
    <scene>
      <ambient>0.4 0.4 0.4 1</ambient>
      <background>0.7 0.7 0.7 1</background>
      <shadows>1</shadows>
    </scene>
    <audio>
      <device>default</device>
    </audio>
    <wind/>
    <spherical_coordinates>
      <surface_model>EARTH_WGS84</surface_model>
      <latitude_deg>0</latitude_deg>
      <longitude_deg>0</longitude_deg>
      <elevation>0</elevation>
      <heading_deg>0</heading_deg>
    </spherical_coordinates>
    <state world_name='default'>
      <sim_time>102 592000000</sim_time>
      <real_time>265 500812200</real_time>
      <wall_time>1680359708 113245872</wall_time>
      <iterations>102592</iterations>
      <model name='ground_plane'>
        <pose>0 0 0 0 -0 0</pose>
        <scale>1 1 1</scale>
        <link name='link'>
          <pose>0 0 0 0 -0 0</pose>
          <velocity>0 0 0 0 -0 0</velocity>
          <acceleration>0 0 0 0 -0 0</acceleration>
          <wrench>0 0 0 0 -0 0</wrench>
        </link>
      </model>
      <model name='omni_robot'>
        <pose>0 0 -51573.5 0 -0 0</pose>
        <scale>1 1 1</scale>
        <link name='base_footprint'>
          <pose>0 0 -51573.5 0 -0 0</pose>
          <velocity>0 0 -1005.4 0 -0 0</velocity>
          <acceleration>0 0 -9.8 0 -0 0</acceleration>
          <wrench>0 0 -9.8 0 -0 0</wrench>
        </link>
        <link name='base_link'>
          <pose>-0.513281 -0.475091 0.152511 -0.000116 -3.1e-05 1.7647</pose>
          <velocity>0.01011 -0.024357 -0.003651 0.064252 -0.042162 0.141907</velocity>
          <acceleration>-1.04106 -1.69317 -4.0777 2.56999 -1.54883 1.79808</acceleration>
          <wrench>-1.21492 -1.97593 -4.75867 0 -0 0</wrench>
        </link>
        <link name='first_wheel_link'>
          <pose>-0.445196 -0.373734 0.130524 0.000346 -1.22138 -0.591826</pose>
          <velocity>-0.003394 -0.01334 0.005894 0.161614 0.097212 0.141819</velocity>
          <acceleration>0.809927 0.976726 13.4007 -2.915 -0.600279 1.60321</acceleration>
          <wrench>0.202482 0.244182 3.35017 0 -0 0</wrench>
        </link>
        <link name='fourth_wheel_link'>
          <pose>-0.411923 -0.543174 0.130519 8e-05 -0.632388 -2.16233</pose>
          <velocity>0.020782 -0.00867 -0.003942 -0.090141 0.063273 0.141747</velocity>
          <acceleration>0.886342 0.810276 -4.9012 2.08187 1.41205 1.4938</acceleration>
          <wrench>0.221586 0.202569 -1.2253 0 -0 0</wrench>
        </link>
        <link name='r10_F_roller_link'>
          <pose>-0.442551 -0.368284 0.106509 0.077101 1.09962 1.04801</pose>
          <velocity>-0.006383 -0.01068 0.012787 1.65249 -0.974621 0.071771</velocity>
          <acceleration>3.36864 1.42371 28.1527 0.157173 -0.171876 -1.50405</acceleration>
          <wrench>0.030318 0.012813 0.253374 0 -0 0</wrench>
        </link>
        <link name='r10_R_roller_link'>
          <pose>-0.399099 -0.534845 0.110995 2.09201 0.831204 1.64006</pose>
          <velocity>0.018367 -0.008611 -0.005519 1.37557 -0.710131 1.11827</velocity>
          <acceleration>0.79565 0.874506 -5.02355 -0.908424 -1.44926 -2.01632</acceleration>
          <wrench>0.007161 0.007871 -0.045212 0 -0 0</wrench>
        </link>
        <link name='r10_S_roller_link'>
          <pose>-0.629413 -0.418245 0.146947 2.2213 0.40905 2.06851</pose>
          <velocity>-0.007491 -0.054791 -0.024017 -0.620298 1.4066 0.046805</velocity>
          <acceleration>0.592778 1.36531 -5.19528 0.597023 -1.40728 -0.176383</acceleration>
          <wrench>0.005335 0.012288 -0.046758 0 -0 0</wrench>
        </link>
        <link name='r10_T_roller_link'>
          <pose>-0.564931 -0.594712 0.127121 1.5508 -0.139404 2.69259</pose>
          <velocity>0.02471 -0.027772 -0.042613 1.06732 0.773637 2.82446</velocity>
          <acceleration>0.882099 1.67412 -23.082 1.43206 0.924637 -2.15562</acceleration>
          <wrench>0.007939 0.015067 -0.207738 0 -0 0</wrench>
        </link>
        <link name='r1_F_roller_link'>
          <pose>-0.46731 -0.366108 0.13876 -1.57105 -0.349417 2.55059</pose>
          <velocity>-0.003655 -0.017764 0.008993 1.9929 -1.13297 -0.075815</velocity>
          <acceleration>0.15027 -0.038845 13.7191 0.056901 -0.420593 2.17082</acceleration>
          <wrench>0.001352 -0.00035 0.123472 0 -0 0</wrench>
        </link>
        <link name='r1_R_roller_link'>
          <pose>-0.408974 -0.528021 0.149928 -2.50513 0.10518 2.6275</pose>
          <velocity>0.019866 -0.006499 -0.005512 0.865756 1.48612 -1.11422</velocity>
          <acceleration>1.00449 0.697134 -4.94429 1.1735 -0.357998 2.43342</acceleration>
          <wrench>0.00904 0.006274 -0.044499 0 -0 0</wrench>
        </link>
        <link name='r1_S_roller_link'>
          <pose>-0.597908 -0.392865 0.142134 1.07093 -0.070153 2.42236</pose>
          <velocity>-0.008037 -0.045808 0.01955 2.25962 1.34509 2.09995</velocity>
          <acceleration>0.640371 1.26597 -5.02389 -1.06191 0.049861 -1.60574</acceleration>
          <wrench>0.005763 0.011394 -0.045215 0 -0 0</wrench>
        </link>
        <link name='r1_T_roller_link'>
          <pose>-0.581463 -0.569154 0.154203 0.845001 1.33812 -1.33087</pose>
          <velocity>0.047719 -0.05051 -0.007078 1.54449 -1.48423 -2.16675</velocity>
          <acceleration>-1.31468 -1.73889 -21.302 -0.985436 0.484682 0.24011</acceleration>
          <wrench>-0.011832 -0.01565 -0.191718 0 -0 0</wrench>
        </link>
        <link name='r2_F_roller_link'>
          <pose>-0.460844 -0.370449 0.111565 -1.0546 -0.783831 -1.26851</pose>
          <velocity>-0.005734 -0.012523 0.007667 -0.542621 0.570468 0.802612</velocity>
          <acceleration>2.42333 3.50468 13.7034 -1.01473 0.284122 -0.728717</acceleration>
          <wrench>0.02181 0.031542 0.12333 0 -0 0</wrench>
        </link>
        <link name='r2_R_roller_link'>
          <pose>-0.404159 -0.520856 0.12299 -1.39889 0.269143 1.55793</pose>
          <velocity>0.017144 -0.008246 -0.006466 -0.909831 -1.1572 1.96146</velocity>
          <acceleration>0.880082 0.823355 -4.93745 -1.99759 -0.076623 2.01875</acceleration>
          <wrench>0.007921 0.00741 -0.044437 0 -0 0</wrench>
        </link>
        <link name='r2_S_roller_link'>
          <pose>-0.612192 -0.414128 0.154134 -1.8754 -1.3713 -1.85191</pose>
          <velocity>-0.012629 -0.059012 -0.009271 -0.46521 1.17581 -2.39807</velocity>
          <acceleration>0.497841 1.4086 -5.03545 -1.69143 -0.229853 2.19747</acceleration>
          <wrench>0.004481 0.012677 -0.045319 0 -0 0</wrench>
        </link>
        <link name='r2_T_roller_link'>
          <pose>-0.560369 -0.583321 0.141772 -1.08734 0.065212 -2.28559</pose>
          <velocity>0.037511 -0.038158 -0.03854 -2.93131 -0.761186 0.529269</velocity>
          <acceleration>-0.326114 -0.179167 -21.3278 2.91793 -0.774296 0.040716</acceleration>
          <wrench>-0.002935 -0.001613 -0.19195 0 -0 0</wrench>
        </link>
        <link name='r3_F_roller_link'>
          <pose>-0.437377 -0.386212 0.110568 2.22817 -0.786917 1.72161</pose>
          <velocity>-0.003593 -0.009033 0.002839 -1.73295 1.3702 -1.39457</velocity>
          <acceleration>2.48834 3.60672 13.6169 -1.64462 -0.237129 0.183546</acceleration>
          <wrench>0.022395 0.032461 0.122552 0 -0 0</wrench>
        </link>
        <link name='r3_R_roller_link'>
          <pose>-0.416955 -0.539906 0.106485 3.13763 0.242689 -0.592433</pose>
          <velocity>0.018473 -0.012647 -0.011309 -1.49178 0.390455 -3.01254</velocity>
          <acceleration>1.04744 -1.17178 -20.5885 2.69338 -0.247926 2.78219</acceleration>
          <wrench>0.009427 -0.010546 -0.185297 0 -0 0</wrench>
        </link>
        <link name='r3_S_roller_link'>
          <pose>-0.622969 -0.430174 0.133481 -1.66427 0.081557 0.124147</pose>
          <velocity>0.002745 -0.041355 -0.031039 1.04242 -0.46628 1.75649</velocity>
          <acceleration>0.760432 1.25281 -5.00752 2.09678 0.747567 -1.41256</acceleration>
          <wrench>0.006844 0.011275 -0.045068 0 -0 0</wrench>
        </link>
        <link name='r3_T_roller_link'>
          <pose>-0.563664 -0.581106 0.113764 -1.72635 0.756428 -0.81618</pose>
          <velocity>0.009616 -0.017522 -0.033659 -2.80978 -0.842492 -2.75164</velocity>
          <acceleration>2.01613 3.35827 -21.301 0.762823 -0.98248 -2.86248</acceleration>
          <wrench>0.018145 0.030224 -0.191709 0 -0 0</wrench>
        </link>
        <link name='r4_F_roller_link'>
          <pose>-0.429339 -0.391614 0.137147 1.82169 -0.123127 -1.71508</pose>
          <velocity>-0.000193 -0.012117 0.00119 2.32181 -1.35398 -2.67055</velocity>
          <acceleration>0.252963 0.12548 13.5927 -3.02764 0.07842 2.82308</acceleration>
          <wrench>0.002277 0.001129 0.122334 0 -0 0</wrench>
        </link>
        <link name='r4_R_roller_link'>
          <pose>-0.42968 -0.558851 0.123175 1.68297 -0.289696 0.603504</pose>
          <velocity>0.022556 -0.01183 -0.001074 -0.816523 -1.0178 -2.08089</velocity>
          <acceleration>0.83025 0.907994 -4.26258 -2.04197 0.727624 2.48449</acceleration>
          <wrench>0.007472 0.008172 -0.038363 0 -0 0</wrench>
        </link>
        <link name='r4_S_roller_link'>
          <pose>-0.615346 -0.418827 0.108715 -2.70329 0.027831 2.56313</pose>
          <velocity>0.01684 -0.017237 -0.015674 0.868514 -0.725239 0.193914</velocity>
          <acceleration>1.06882 1.01588 -4.98825 2.81673 1.38205 1.32557</acceleration>
          <wrench>0.009619 0.009143 -0.044894 0 -0 0</wrench>
        </link>
        <link name='r4_T_roller_link'>
          <pose>-0.586794 -0.565568 0.108885 1.98189 -1.07083 -1.05248</pose>
          <velocity>0.002587 -0.017123 0.00081 1.53152 0.461994 -0.315552</velocity>
          <acceleration>2.48168 3.98091 -21.2755 -2.75699 -0.792306 -2.71818</acceleration>
          <wrench>0.022335 0.035828 -0.19148 0 -0 0</wrench>
        </link>
        <link name='r5_F_roller_link'>
          <pose>-0.447839 -0.379189 0.15457 3.0913 0.793759 -2.19817</pose>
          <velocity>-0.000232 -0.017513 0.005004 1.18221 -0.4426 3.10698</velocity>
          <acceleration>-1.19281 -2.12814 13.6725 -1.24896 -0.009045 2.54487</acceleration>
          <wrench>-0.010735 -0.019153 0.123052 0 -0 0</wrench>
        </link>
        <link name='r5_R_roller_link'>
          <pose>-0.424746 -0.551502 0.150042 1.21353 -0.897091 -1.71663</pose>
          <velocity>0.023184 -0.008695 -0.002049 -0.073102 0.088306 0.164517</velocity>
          <acceleration>0.917143 0.786195 -4.24946 2.42618 -0.479965 2.43103</acceleration>
          <wrench>0.008254 0.007076 -0.038245 0 -0 0</wrench>
        </link>
        <link name='r5_S_roller_link'>
          <pose>-0.599858 -0.395769 0.114063 1.37786 -0.731864 -1.87786</pose>
          <velocity>0.010177 -0.019989 0.015586 0.564941 -0.357476 2.31516</velocity>
          <acceleration>0.996 1.02406 -5.01025 1.16304 0.887865 1.42467</acceleration>
          <wrench>0.008964 0.009217 -0.045092 0 -0 0</wrench>
        </link>
        <link name='r5_T_roller_link'>
          <pose>-0.597794 -0.558182 0.133878 1.69707 0.062498 0.521598</pose>
          <velocity>0.026136 -0.037513 0.017214 0.873266 0.904199 1.16461</velocity>
          <acceleration>0.423147 0.826222 -21.317 2.31361 0.544198 1.41784</acceleration>
          <wrench>0.003808 0.007436 -0.191853 0 -0 0</wrench>
        </link>
        <link name='r6_F_roller_link'>
          <pose>-0.423082 -0.38136 0.122285 -1.66552 -0.336844 2.82972</pose>
          <velocity>-0.003119 -0.008866 0.002213 0.291449 1.02096 -0.385251</velocity>
          <acceleration>1.51551 2.0588 15.4775 1.26369 -1.46446 -2.75623</acceleration>
          <wrench>0.01364 0.018529 0.139297 0 -0 0</wrench>
        </link>
        <link name='r6_R_roller_link'>
          <pose>-0.414872 -0.558327 0.111108 -0.679894 -0.347777 -0.322657</pose>
          <velocity>0.021732 -0.010822 -0.002047 -0.126301 -1.54341 -0.797323</velocity>
          <acceleration>0.79818 0.939371 -4.30983 0.783966 0.266546 0.036138</acceleration>
          <wrench>0.007184 0.008454 -0.038788 0 -0 0</wrench>
        </link>
        <link name='r6_S_roller_link'>
          <pose>-0.631363 -0.42115 0.118877 1.08433 -0.138807 2.29416</pose>
          <velocity>0.010724 -0.02897 -0.027987 0.432847 -1.37368 1.75883</velocity>
          <acceleration>0.950898 1.12659 -5.19836 2.87568 -1.08207 0.2574</acceleration>
          <wrench>0.008558 0.010139 -0.046785 0 -0 0</wrench>
        </link>
        <link name='r6_T_roller_link'>
          <pose>-0.581265 -0.583738 0.106823 2.6193 -1.21975 1.47483</pose>
          <velocity>0.003971 -0.01526 -0.024881 2.8197 -0.684355 0.602926</velocity>
          <acceleration>5.18345 3.64045 -32.5252 -0.90561 -1.39819 -1.00771</acceleration>
          <wrench>0.046651 0.032764 -0.292727 0 -0 0</wrench>
        </link>
        <link name='r7_F_roller_link'>
          <pose>-0.429548 -0.377019 0.14948 -2.43269 -0.329708 0.708533</pose>
          <velocity>-0.001047 -0.014109 0.003551 2.15746 0.212698 -1.55696</velocity>
          <acceleration>-0.768255 -1.48948 15.5134 1.52373 -1.44333 0.637671</acceleration>
          <wrench>-0.006914 -0.013405 0.13962 0 -0 0</wrench>
        </link>
        <link name='r7_R_roller_link'>
          <pose>-0.419686 -0.565491 0.138047 -1.88018 0.075746 -0.358848</pose>
          <velocity>0.024424 -0.009064 -0.001101 0.213921 0.51568 1.80025</velocity>
          <acceleration>0.865025 0.830561 -4.33149 -2.17967 0.71003 -3.028</acceleration>
          <wrench>0.007785 0.007475 -0.038983 0 -0 0</wrench>
        </link>
        <link name='r7_S_roller_link'>
          <pose>-0.617079 -0.399886 0.106903 -2.9424 -0.314451 -0.65387</pose>
          <velocity>0.015319 -0.015707 -0.005985 0.050823 0.808293 -2.28434</velocity>
          <acceleration>0.506188 0.902915 -21.2955 -3.102 -1.3761 2.64717</acceleration>
          <wrench>0.004556 0.008126 -0.191659 0 -0 0</wrench>
        </link>
        <link name='r7_T_roller_link'>
          <pose>-0.602355 -0.569572 0.119226 -1.44941 -0.473323 -0.852758</pose>
          <velocity>0.013288 -0.027146 0.013485 2.26651 -0.031579 2.98447</velocity>
          <acceleration>1.56303 2.64123 -22.5873 0.726264 1.55906 2.2184</acceleration>
          <wrench>0.014067 0.023771 -0.203286 0 -0 0</wrench>
        </link>
        <link name='r8_F_roller_link'>
          <pose>-0.453015 -0.361256 0.150477 1.27465 0.946736 -0.951193</pose>
          <velocity>-0.003187 -0.017601 0.008386 2.03471 -1.16123 1.66515</velocity>
          <acceleration>-0.830898 -1.59383 15.6113 -0.296287 -0.616041 -1.37986</acceleration>
          <wrench>-0.007478 -0.014344 0.140502 0 -0 0</wrench>
        </link>
        <link name='r8_R_roller_link'>
          <pose>-0.406889 -0.546438 0.154581 0.004747 -0.542889 2.54766</pose>
          <velocity>0.022751 -0.005751 -0.003626 -1.11828 -0.067185 -3.01501</velocity>
          <acceleration>0.941429 0.739721 -4.28951 1.85101 1.56414 -2.14778</acceleration>
          <wrench>0.008473 0.006657 -0.038606 0 -0 0</wrench>
        </link>
        <link name='r8_S_roller_link'>
          <pose>-0.606302 -0.38384 0.127528 -1.56825 -0.123948 -2.18241</pose>
          <velocity>-7e-05 -0.033413 0.022996 0.65023 -1.05062 2.38284</velocity>
          <acceleration>0.819046 1.16171 -4.29233 -1.77913 -1.3609 -2.88532</acceleration>
          <wrench>0.007371 0.010455 -0.038631 0 -0 0</wrench>
        </link>
        <link name='r8_T_roller_link'>
          <pose>-0.599061 -0.571788 0.147234 -2.27047 -0.350598 -2.5498</pose>
          <velocity>0.041244 -0.047691 0.008576 0.514394 1.14535 -0.151757</velocity>
          <acceleration>-0.695652 -0.760277 -22.6631 1.50157 0.885936 -1.00555</acceleration>
          <wrench>-0.006261 -0.006842 -0.203968 0 -0 0</wrench>
        </link>
        <link name='r9_F_roller_link'>
          <pose>-0.461052 -0.355854 0.123898 1.80407 -0.154292 -1.58784</pose>
          <velocity>-0.006579 -0.014509 0.010048 -1.07421 0.927498 -0.954011</velocity>
          <acceleration>1.41771 1.89868 15.6545 -2.51521 0.357101 1.07534</acceleration>
          <wrench>0.012759 0.017088 0.14089 0 -0 0</wrench>
        </link>
        <link name='r9_R_roller_link'>
          <pose>-0.394165 -0.527497 0.13786 1.27391 0.090874 2.83831</pose>
          <velocity>0.019024 -0.005459 -0.006136 -1.61929 0.679514 0.543836</velocity>
          <acceleration>0.921345 0.795334 -4.24818 2.2134 -0.56624 1.69893</acceleration>
          <wrench>0.008292 0.007158 -0.038234 0 -0 0</wrench>
        </link>
        <link name='r9_S_roller_link'>
          <pose>-0.613925 -0.395187 0.152294 -2.61995 -0.552207 2.25723</pose>
          <velocity>-0.014073 -0.05759 0.007625 -1.40309 -1.03779 3.1043</velocity>
          <acceleration>0.719769 1.26383 -4.32756 1.00341 -1.18615 -1.35122</acceleration>
          <wrench>0.006478 0.011374 -0.038948 0 -0 0</wrench>
        </link>
        <link name='r9_T_roller_link'>
          <pose>-0.575931 -0.587326 0.152112 2.58042 0.599272 -2.50294</pose>
          <velocity>0.04828 -0.048084 -0.025917 -2.38247 0.098499 -0.418974</velocity>
          <acceleration>-1.15118 -1.37396 -22.7242 -1.87238 1.2834 -1.07929</acceleration>
          <wrench>-0.010361 -0.012366 -0.204518 0 -0 0</wrench>
        </link>
        <link name='second_wheel_link'>
          <pose>-0.614636 -0.407007 0.130505 -7.2e-05 1.06645 0.979239</pose>
          <velocity>0.001338 -0.037393 -0.004194 0.929784 -0.634009 0.142388</velocity>
          <acceleration>0.781987 1.18548 -4.8785 2.43858 -0.476053 -0.522976</acceleration>
          <wrench>0.195497 0.296369 -1.21962 0 -0 0</wrench>
        </link>
        <link name='third_wheel_link'>
          <pose>-0.581362 -0.576447 0.130499 -9.4e-05 0.173335 2.55008</pose>
          <velocity>0.025409 -0.032622 -0.012642 0.751397 0.985836 0.14204</velocity>
          <acceleration>0.64648 1.26232 -20.5709 0.549769 -0.141249 -1.40649</acceleration>
          <wrench>0.16162 0.315579 -5.14274 0 -0 0</wrench>
        </link>
      </model>
      <model name='omni_stage'>
        <pose>0 0 0 0 -0 0</pose>
        <scale>1 1 1</scale>
        <link name='link'>
          <pose>0 0 0 0 -0 0</pose>
          <velocity>0 0 0 0 -0 0</velocity>
          <acceleration>0 0 0 0 -0 0</acceleration>
          <wrench>0 0 0 0 -0 0</wrench>
        </link>
      </model>
      <light name='sun'>
        <pose>0 0 10 0 -0 0</pose>
      </light>
    </state>
    <gui fullscreen='0'>
      <camera name='user_camera'>
        <pose>4.6602 -5.393 1.86701 0 0.275643 2.35619</pose>
        <view_controller>orbit</view_controller>
        <projection_type>perspective</projection_type>
      </camera>
    </gui>
  </world>
</sdf>
